Workbook

Sheet Thickness
A1: 2025 | C1: NC - NOT CLEAN; | DQ1: OBSTRUCTION
C2: TUBES NUMBERED LEFT TO RIGHT FACING WALL. THICKNESS MEASUREMENTS ARE IN INCHES. | DQ2: ORIENTATION
A3: ELEVATION | C3: LOC | D3: 1 | E3: 2 | F3: 3 | G3: 4 | H3: 5 | I3: 6 | J3: 7 | K3: 8 | L3: 9 | M3: 10 | N3: 11 | O3: 12 | P3: 13 | Q3: 14 | R3: 15 | S3: 16 | T3: 17 | U3: 18 | V3: 19 | W3: 20 | X3: 21 | Y3: 22 | Z3: 23 | AA3: 24 | AB3: 25 | AC3: 26 | AD3: 27 | AE3: 28 | AF3: 29 | AG3: 30 | AH3: 31 | AI3: 32 | AJ3: 33 | AK3: 34 | AL3: 35 | AM3: 36 | AN3: 37 | AO3: 38 | AP3: 39 | AQ3: 40 | AR3: 41 | AS3: 42 | AT3: 43 | AU3: 44 | AV3: 45 | AW3: 46 | AX3: 47 | AY3: 48 | AZ3: 49 | BA3: 50 | BB3: 51 | BC3: 52 | BD3: 53 | BE3: 54 | BF3: 55 | BG3: 56 | BH3: 57 | BI3: 58 | BJ3: 59 | BK3: 60 | BL3: 61 | BM3: 62 | BN3: AVG | BO3: MIN
A4: A | C4: L | D4: 0.349 | E4: 0.364 | F4: 0.343 | G4: 0.334 | H4: 0.356 | I4: 0.351 | J4: 0.344 | K4: 0.34 | L4: 0.352 | M4: 0.345 | N4: 0.333 | O4: 0.342 | P4: 0.331 | Q4: 0.372 | R4: 0.322 | S4: 0.333 | T4: 0.297 | U4: 0.364 | V4: 0.317 | W4: 0.322 | X4: 0.341 | Y4: 0.31 | Z4: 0.327 | AA4: 0.321 | AB4: 0.332 | AC4: 0.339 | AD4: 0.331 | AE4: 0.328 | AF4: 0.323 | AG4: 0.32 | AH4: 0.331 | AI4: 0.337 | AJ4: 0.327 | AK4: 0.347 | AL4: 0.358 | AM4: 0.325 | AN4: 0.334 | AO4: 0.325 | AP4: 0.33 | AQ4: 0.362 | AR4: 0.333 | AS4: 0.331 | AT4: 0.319 | AU4: 0.327 | AV4: 0.347 | AW4: 0.334 | AX4: 0.341 | AY4: 0.324 | AZ4: 0.329 | BA4: 0.332 | BB4: 0.331 | BC4: 0.333 | BD4: 0.328 | BE4: 0.333 | BF4: 0.394 | BG4: 0.333 | BH4: 0.339 | BI4: 0.344 | BJ4: 0.351 | BK4: 0.356 | BL4: 0.341 | BM4: 0.35 | BN4: =IFERROR(AVERAGE(D4:BM6),0) -> 0.33731183 | BO4: =MIN(D4:BM6) -> 0.297
A5: 0.083 | B5: 0 REFERENCE | C5: C | D5: 0.352 | E5: 0.344 | F5: 0.343 | G5: 0.34 | H5: 0.352 | I5: 0.357 | J5: 0.359 | K5: 0.331 | L5: 0.334 | M5: 0.327 | N5: 0.312 | O5: 0.351 | P5: 0.322 | Q5: 0.332 | R5: 0.317 | S5: 0.321 | T5: 0.322 | U5: 0.31 | V5: 0.305 | W5: 0.327 | X5: 0.323 | Y5: 0.332 | Z5: 0.314 | AA5: 0.336 | AB5: 0.334 | AC5: 0.33 | AD5: 0.331 | AE5: 0.353 | AF5: 0.323 | AG5: 0.31 | AH5: 0.331 | AI5: 0.321 | AJ5: 0.319 | AK5: 0.333 | AL5: 0.314 | AM5: 0.322 | AN5: 0.332 | AO5: 0.319 | AP5: 0.362 | AQ5: 0.327 | AR5: 0.324 | AS5: 0.325 | AT5: 0.316 | AU5: 0.315 | AV5: 0.363 | AW5: 0.334 | AX5: 0.333 | AY5: 0.335 | AZ5: 0.327 | BA5: 0.317 | BB5: 0.335 | BC5: 0.329 | BD5: 0.326 | BE5: 0.355 | BF5: 0.345 | BG5: 0.351 | BH5: 0.351 | BI5: 0.395 | BJ5: 0.353 | BK5: 0.343 | BL5: 0.357 | BM5: 0.344 | BN5: =IFERROR(AVERAGE(D5:BM7),0) -> 0.32921081 | BO5: =MIN(D5:BM7) -> 0.288
C6: R | D6: 0.393 | E6: 0.385 | F6: 0.344 | G6: 0.333 | H6: 0.368 | I6: 0.356 | J6: 0.359 | K6: 0.334 | L6: 0.32 | M6: 0.34 | N6: 0.356 | O6: 0.352 | P6: 0.323 | Q6: 0.343 | R6: 0.32 | S6: 0.314 | T6: 0.357 | U6: 0.347 | V6: 0.329 | W6: 0.355 | X6: 0.313 | Y6: 0.34 | Z6: 0.342 | AA6: 0.337 | AB6: 0.336 | AC6: 0.33 | AD6: 0.338 | AE6: 0.331 | AF6: 0.333 | AG6: 0.308 | AH6: 0.333 | AI6: 0.358 | AJ6: 0.338 | AK6: 0.322 | AL6: 0.345 | AM6: 0.317 | AN6: 0.349 | AO6: 0.331 | AP6: 0.336 | AQ6: 0.33 | AR6: 0.332 | AS6: 0.327 | AT6: 0.327 | AU6: 0.313 | AV6: 0.352 | AW6: 0.331 | AX6: 0.321 | AY6: 0.334 | AZ6: 0.327 | BA6: 0.329 | BB6: 0.332 | BC6: 0.317 | BD6: 0.343 | BE6: 0.325 | BF6: 0.391 | BG6: 0.359 | BH6: 0.345 | BI6: 0.398 | BJ6: 0.373 | BK6: 0.367 | BL6: 0.351 | BM6: 0.345 | BN6: =IFERROR(AVERAGE(D6:BM8),0) -> 0.32131351 | BO6: =MIN(D6:BM8) -> 0.288
A7: A | C7: L | D7: 0.338 | E7: NC | F7: 0.33 | G7: 0.359 | H7: 0.327 | I7: 0.327 | J7: 0.32 | K7: 0.317 | L7: 0.319 | M7: 0.301 | N7: 0.309 | O7: 0.301 | P7: 0.294 | Q7: 0.297 | R7: 0.319 | S7: 0.297 | T7: 0.309 | U7: 0.31 | V7: 0.309 | W7: 0.303 | X7: 0.312 | Y7: 0.328 | Z7: 0.318 | AA7: 0.317 | AB7: 0.313 | AC7: 0.333 | AD7: 0.338 | AE7: 0.326 | AF7: 0.314 | AG7: 0.312 | AH7: 0.31 | AI7: 0.324 | AJ7: 0.311 | AK7: 0.304 | AL7: 0.323 | AM7: 0.318 | AN7: 0.3 | AO7: 0.312 | AP7: 0.31 | AQ7: 0.312 | AR7: 0.308 | AS7: 0.342 | AT7: 0.308 | AU7: 0.302 | AV7: 0.298 | AW7: 0.312 | AX7: 0.296 | AY7: 0.298 | AZ7: 0.294 | BA7: 0.288 | BB7: 0.292 | BC7: 0.308 | BD7: 0.308 | BE7: 0.303 | BF7: 0.308 | BG7: 0.308 | BH7: 0.312 | BI7: 0.319 | BJ7: 0.326 | BK7: 0.326 | BL7: 0.297 | BM7: 0.299 | BN7: =IFERROR(AVERAGE(D7:BM9),0) -> 0.31223243 | BO7: =MIN(D7:BM9) -> 0.284
A8: 0.083 | B8: -6 FEET | C8: C | D8: 0.332 | E8: 0.325 | F8: 0.323 | G8: 0.361 | H8: 0.311 | I8: 0.318 | J8: 0.32 | K8: 0.314 | L8: 0.312 | M8: 0.297 | N8: 0.294 | O8: 0.299 | P8: 0.293 | Q8: 0.308 | R8: 0.315 | S8: 0.319 | T8: 0.314 | U8: 0.303 | V8: 0.306 | W8: 0.315 | X8: 0.319 | Y8: 0.302 | Z8: 0.299 | AA8: 0.302 | AB8: 0.307 | AC8: 0.306 | AD8: 0.341 | AE8: 0.322 | AF8: 0.311 | AG8: 0.304 | AH8: 0.323 | AI8: 0.312 | AJ8: 0.311 | AK8: 0.319 | AL8: 0.318 | AM8: 0.318 | AN8: 0.305 | AO8: 0.305 | AP8: 0.319 | AQ8: 0.309 | AR8: 0.3 | AS8: 0.311 | AT8: 0.293 | AU8: 0.303 | AV8: 0.293 | AW8: 0.301 | AX8: 0.3 | AY8: 0.297 | AZ8: 0.299 | BA8: 0.298 | BB8: 0.297 | BC8: 0.307 | BD8: 0.304 | BE8: 0.3 | BF8: 0.305 | BG8: 0.312 | BH8: 0.309 | BI8: 0.322 | BJ8: 0.323 | BK8: 0.335 | BL8: 0.297 | BM8: 0.299 | BN8: =IFERROR(AVERAGE(D8:BM10),0) -> 0.31485057 | BO8: =MIN(D8:BM10) -> 0.284
C9: R | D9: 0.334 | E9: 0.337 | F9: 0.323 | G9: 0.308 | H9: 0.313 | I9: 0.315 | J9: 0.319 | K9: 0.313 | L9: 0.312 | M9: 0.301 | N9: 0.302 | O9: 0.306 | P9: 0.306 | Q9: 0.293 | R9: 0.289 | S9: 0.324 | T9: 0.316 | U9: 0.317 | V9: 0.306 | W9: 0.319 | X9: 0.33 | Y9: 0.318 | Z9: 0.292 | AA9: 0.324 | AB9: 0.317 | AC9: 0.321 | AD9: 0.331 | AE9: 0.319 | AF9: 0.356 | AG9: 0.315 | AH9: 0.314 | AI9: 0.32 | AJ9: 0.323 | AK9: 0.315 | AL9: 0.324 | AM9: 0.315 | AN9: 0.301 | AO9: 0.304 | AP9: 0.35 | AQ9: 0.315 | AR9: 0.314 | AS9: 0.303 | AT9: 0.309 | AU9: 0.309 | AV9: 0.3 | AW9: 0.31 | AX9: 0.284 | AY9: 0.31 | AZ9: 0.294 | BA9: 0.339 | BB9: 0.304 | BC9: 0.306 | BD9: 0.299 | BE9: 0.308 | BF9: 0.316 | BG9: 0.308 | BH9: 0.309 | BI9: 0.317 | BJ9: 0.317 | BK9: 0.299 | BL9: 0.307 | BM9: 0.335 | BN9: =IFERROR(AVERAGE(D9:BM11),0) -> 0.31681875 | BO9: =MIN(D9:BM11) -> 0.277
A10: A | C10: L | D10: NC | E10: NC | F10: NC | G10: NC | H10: 0.324 | I10: 0.323 | J10: 0.389 | K10: 0.355 | L10: 0.323 | M10: 0.313 | N10: 0.314 | O10: 0.315 | P10: 0.309 | Q10: 0.316 | R10: 0.323 | S10: 0.292 | T10: 0.322 | U10: 0.344 | V10: 0.318 | W10: 0.315 | X10: 0.36 | Y10: 0.33 | Z10: NC | AA10: 0.306 | AB10: NC | AC10: 0.332 | AD10: NC | AE10: 0.321 | AF10: 0.33 | AG10: 0.318 | AH10: 0.323 | AI10: 0.33 | AJ10: NC | AK10: 0.308 | AL10: 0.354 | AM10: 0.31 | AN10: 0.314 | AO10: 0.317 | AP10: 0.313 | AQ10: 0.332 | AR10: 0.321 | AS10: 0.312 | AT10: 0.321 | AU10: 0.328 | AV10: 0.327 | AW10: 0.317 | AX10: 0.308 | AY10: 0.315 | AZ10: 0.315 | BA10: 0.32 | BB10: 0.306 | BC10: 0.314 | BD10: 0.319 | BE10: 0.314 | BF10: 0.312 | BG10: 0.328 | BH10: 0.301 | BI10: NC | BJ10: 0.323 | BK10: NC | BL10: NC | BM10: NC | BN10: =IFERROR(AVERAGE(D10:BM12),0) -> 0.31993878 | BO10: =MIN(D10:BM12) -> 0.277
A11: 0.083 | B11: -12 FEET | C11: C | D11: NC | E11: NC | F11: NC | G11: NC | H11: 0.323 | I11: 0.348 | J11: 0.381 | K11: 0.277 | L11: 0.307 | M11: 0.316 | N11: 0.315 | O11: 0.318 | P11: 0.315 | Q11: 0.318 | R11: 0.296 | S11: 0.32 | T11: 0.334 | U11: 0.319 | V11: 0.318 | W11: 0.31 | X11: 0.33 | Y11: NC | Z11: NC | AA11: 0.307 | AB11: NC | AC11: 0.312 | AD11: NC | AE11: 0.328 | AF11: 0.335 | AG11: 0.315 | AH11: 0.315 | AI11: 0.33 | AJ11: NC | AK11: 0.304 | AL11: NC | AM11: 0.309 | AN11: 0.319 | AO11: 0.299 | AP11: 0.315 | AQ11: 0.334 | AR11: 0.323 | AS11: 0.321 | AT11: 0.316 | AU11: 0.316 | AV11: 0.32 | AW11: 0.311 | AX11: 0.319 | AY11: 0.307 | AZ11: 0.313 | BA11: 0.318 | BB11: 0.295 | BC11: 0.295 | BD11: 0.299 | BE11: 0.302 | BF11: 0.289 | BG11: 0.301 | BH11: 0.309 | BI11: NC | BJ11: 0.322 | BK11: NC | BL11: NC | BM11: NC | BN11: =IFERROR(AVERAGE(D11:BM13),0) -> 0.31893814 | BO11: =MIN(D11:BM13) -> 0.277
C12: R | D12: NC | E12: NC | F12: NC | G12: NC | H12: 0.324 | I12: 0.353 | J12: 0.383 | K12: 0.345 | L12: 0.308 | M12: 0.311 | N12: 0.308 | O12: 0.319 | P12: 0.312 | Q12: 0.316 | R12: 0.326 | S12: 0.317 | T12: 0.343 | U12: 0.314 | V12: 0.315 | W12: 0.314 | X12: 0.322 | Y12: 0.332 | Z12: 0.308 | AA12: 0.309 | AB12: NC | AC12: NC | AD12: NC | AE12: 0.337 | AF12: 0.336 | AG12: 0.317 | AH12: 0.329 | AI12: 0.339 | AJ12: NC | AK12: 0.355 | AL12: NC | AM12: 0.312 | AN12: 0.319 | AO12: 0.38 | AP12: 0.31 | AQ12: 0.333 | AR12: 0.332 | AS12: 0.333 | AT12: 0.31 | AU12: 0.33 | AV12: 0.313 | AW12: 0.318 | AX12: 0.318 | AY12: 0.31 | AZ12: 0.32 | BA12: 0.32 | BB12: 0.303 | BC12: 0.314 | BD12: 0.297 | BE12: 0.311 | BF12: 0.294 | BG12: 0.302 | BH12: 0.311 | BI12: NC | BJ12: 0.312 | BK12: NC | BL12: NC | BM12: NC | BN12: =IFERROR(AVERAGE(D12:BM14),0) -> 0.32232653 | BO12: =MIN(D12:BM14) -> 0.294
A13: A | C13: L | D13: NC | E13: NC | F13: NC | G13: NC | H13: NC | I13: NC | J13: NC | K13: NC | L13: NC | M13: NC | N13: NC | O13: NC | P13: NC | Q13: NC | R13: NC | S13: NC | T13: NC | U13: NC | V13: NC | W13: NC | X13: NC | Y13: NC | Z13: NC | AA13: NC | AB13: NC | AC13: NC | AD13: NC | AE13: NC | AF13: NC | AG13: NC | AH13: NC | AI13: NC | AJ13: NC | AK13: NC | AL13: NC | AM13: NC | AN13: NC | AO13: NC | AP13: NC | AQ13: NC | AR13: NC | AS13: NC | AT13: NC | AU13: NC | AV13: NC | AW13: NC | AX13: NC | AY13: NC | AZ13: NC | BA13: NC | BB13: NC | BC13: NC | BD13: NC | BE13: NC | BF13: NC | BG13: NC | BH13: NC | BI13: NC | BJ13: NC | BK13: NC | BL13: NC | BM13: NC | BN13: =IFERROR(AVERAGE(D13:BM15),0) -> 0 | BO13: =MIN(D13:BM15) -> 0
A14: 0.083 | B14: -18 FEET | C14: C | D14: NC | E14: NC | F14: NC | G14: NC | H14: NC | I14: NC | J14: NC | K14: NC | L14: NC | M14: NC | N14: NC | O14: NC | P14: NC | Q14: NC | R14: NC | S14: NC | T14: NC | U14: NC | V14: NC | W14: NC | X14: NC | Y14: NC | Z14: NC | AA14: NC | AB14: NC | AC14: NC | AD14: NC | AE14: NC | AF14: NC | AG14: NC | AH14: NC | AI14: NC | AJ14: NC | AK14: NC | AL14: NC | AM14: NC | AN14: NC | AO14: NC | AP14: NC | AQ14: NC | AR14: NC | AS14: NC | AT14: NC | AU14: NC | AV14: NC | AW14: NC | AX14: NC | AY14: NC | AZ14: NC | BA14: NC | BB14: NC | BC14: NC | BD14: NC | BE14: NC | BF14: NC | BG14: NC | BH14: NC | BI14: NC | BJ14: NC | BK14: NC | BL14: NC | BM14: NC | BN14: =IFERROR(AVERAGE(D14:BM16),0) -> 31.5 | BO14: =MIN(D14:BM16) -> 1
C15: R | D15: NC | E15: NC | F15: NC | G15: NC | H15: NC | I15: NC | J15: NC | K15: NC | L15: NC | M15: NC | N15: NC | O15: NC | P15: NC | Q15: NC | R15: NC | S15: NC | T15: NC | U15: NC | V15: NC | W15: NC | X15: NC | Y15: NC | Z15: NC | AA15: NC | AB15: NC | AC15: NC | AD15: NC | AE15: NC | AF15: NC | AG15: NC | AH15: NC | AI15: NC | AJ15: NC | AK15: NC | AL15: NC | AM15: NC | AN15: NC | AO15: NC | AP15: NC | AQ15: NC | AR15: NC | AS15: NC | AT15: NC | AU15: NC | AV15: NC | AW15: NC | AX15: NC | AY15: NC | AZ15: NC | BA15: NC | BB15: NC | BC15: NC | BD15: NC | BE15: NC | BF15: NC | BG15: NC | BH15: NC | BI15: NC | BJ15: NC | BK15: NC | BL15: NC | BM15: NC | BN15: =IFERROR(AVERAGE(D15:BM17),0) -> 31.5 | BO15: =MIN(D15:BM17) -> 1
A16: ELEVATION | C16: LOC | D16: 1 | E16: 2 | F16: 3 | G16: 4 | H16: 5 | I16: 6 | J16: 7 | K16: 8 | L16: 9 | M16: 10 | N16: 11 | O16: 12 | P16: 13 | Q16: 14 | R16: 15 | S16: 16 | T16: 17 | U16: 18 | V16: 19 | W16: 20 | X16: 21 | Y16: 22 | Z16: 23 | AA16: 24 | AB16: 25 | AC16: 26 | AD16: 27 | AE16: 28 | AF16: 29 | AG16: 30 | AH16: 31 | AI16: 32 | AJ16: 33 | AK16: 34 | AL16: 35 | AM16: 36 | AN16: 37 | AO16: 38 | AP16: 39 | AQ16: 40 | AR16: 41 | AS16: 42 | AT16: 43 | AU16: 44 | AV16: 45 | AW16: 46 | AX16: 47 | AY16: 48 | AZ16: 49 | BA16: 50 | BB16: 51 | BC16: 52 | BD16: 53 | BE16: 54 | BF16: 55 | BG16: 56 | BH16: 57 | BI16: 58 | BJ16: 59 | BK16: 60 | BL16: 61 | BM16: 62 | BN16: AVG | BO16: MIN
A97: A | B97: 0.001-0.083 | C97: 0.204-0.233 | M97: OUTSIDE DIAMETER: | Z97: 3 | AG97: INSPECTION RESULTS | BR97: APPLIED TECHNICAL SERVICES 1049 Triad Court Marietta, Georgia 30062 Office # (770) 423-1400 Fax # (770) 514-3299 www.atslab.com | CL97: INTERNATIONAL PAPER
A98: LEGEND | B98: 0.084-0.113 | C98: 0.234-0.263 | M98: TUBE MATERIAL: | Z98: SA-210A1 | AG98: =TRUNC(MAX(D4:BM6,D7:BM9,D10:BM12,D13:BM15),3) -> 0.398 | AL98: MAX. THICKNESS | CL98: RIVERDALE MILL
B99: 0.114-0.143 | C99: 0.264-0.293 | M99: NOMINAL WALL: | Z99: 0.3 | AG99: =TRUNC(AVERAGE(D4:BM6,D7:BM9,D10:BM12,D13:BM15),3) -> 0.323 | AL99: AVG. THICKNESS | CL99: TUBE WALL THICKNESS SURVEY
B100: 0.144-0.173 | C100: 0.294-0.323 | M100: ASME MIN: | Z100: 0.083 | AG100: =TRUNC(MIN(D4:BM6,D7:BM9,D10:BM12,D13:BM15),3) -> 0.277 | AL100: MIN. THICKNESS | CL100: NO. 1 RECOVERY BOILER
B101: 0.174-0.203 | C101: 0.324-0.999 | M101: MILL FLAG: | Z101: 0.2 | AG101: =STDEV(D4:BM6,D7:BM9,D10:BM12,D13:BM15) -> 0.019267463 | AL101: STD DEV. | AW101: Job # H449364 P.O. # 0018342455 W.O. # N/A Date: 5/05/2025 | CL101: 01 FLOOR
B102: THICKNESS
BR105: APPLIED TECHNICAL SERVICES 1049 Triad Court Marietta, Georgia 30062 Office # (770) 423-1400 Fax # (770) 514-3299 www.atslab.com
BR110: APPLIED TECHNICAL SERVICES 1325-B Cavalier Boulevard Chesapeake, Virginia 23323 (757) 558-0016 Fax (757) 558-0063 www.atslab.com
BR115: APPLIED TECHNICAL SERVICES 2312 Commerce Ctr. Dr., Suite A Rockville, Virginia 23146 (804) 550-7610 Fax (804) 550-7611 www.atslab.com

Sheet Corrosion
A1: =Thickness!A1 -> 2025 | C1: =IF(ISBLANK(Thickness!C1),"",(Thickness!C1)) -> NC - NOT CLEAN; | DQ1: OBSTRUCTION
C2: TUBES NUMBERED LEFT TO RIGHT FACING WALL. CORROSION RATE MEASUREMENTS ARE IN MILS. | DQ2: ORIENTATION
A3: ELEVATION | C3: LOC | D3: 1 | E3: 2 | F3: 3 | G3: 4 | H3: 5 | I3: 6 | J3: 7 | K3: 8 | L3: 9 | M3: 10 | N3: 11 | O3: 12 | P3: 13 | Q3: 14 | R3: 15 | S3: 16 | T3: 17 | U3: 18 | V3: 19 | W3: 20 | X3: 21 | Y3: 22 | Z3: 23 | AA3: 24 | AB3: 25 | AC3: 26 | AD3: 27 | AE3: 28 | AF3: 29 | AG3: 30 | AH3: 31 | AI3: 32 | AJ3: 33 | AK3: 34 | AL3: 35 | AM3: 36 | AN3: 37 | AO3: 38 | AP3: 39 | AQ3: 40 | AR3: 41 | AS3: 42 | AT3: 43 | AU3: 44 | AV3: 45 | AW3: 46 | AX3: 47 | AY3: 48 | AZ3: 49 | BA3: 50 | BB3: 51 | BC3: 52 | BD3: 53 | BE3: 54 | BF3: 55 | BG3: 56 | BH3: 57 | BI3: 58 | BJ3: 59 | BK3: 60 | BL3: 61 | BM3: 62 | BN3: AVG | BO3: MAX
A4: A | C4: L | D4: 2.95 | E4: 4.71 | F4: 3.71 | G4: 5.52 | H4: 2.45 | I4: 0.428 | J4: ND | K4: 0.568 | L4: ND | M4: ND | N4: 2.87 | O4: ND | P4: 4.4 | Q4: ND | R4: 2.49 | S4: 4.27 | T4: 11.8 | U4: ND | V4: 5.69 | W4: 7.47 | X4: 3.3 | Y4: 7.5 | Z4: 2.84 | AA4: 2.13 | AB4: 1.81 | AC4: 0.6 | AD4: 3.06 | AE4: ND | AF4: 5.1 | AG4: 1.95 | AH4: 1.84 | AI4: 2.6 | AJ4: 3.98 | AK4: ND | AL4: ND | AM4: 3.17 | AN4: 2.59 | AO4: 7.23 | AP4: 11.3 | AQ4: ND | AR4: 3.97 | AS4: 3.85 | AT4: 7.9 | AU4: 7.3 | AV4: ND | AW4: 2.64 | AX4: ND | AY4: 1.65 | AZ4: 3.9 | BA4: 3.93 | BB4: 4.29 | BC4: 4.59 | BD4: 4.1 | BE4: 0.646 | BF4: ND | BG4: 5.61 | BH4: 3.92 | BI4: 5.7 | BJ4: 1.99 | BK4: 0.615 | BL4: 4.1 | BM4: 2.17 | BN4: =IFERROR(AVERAGE(D4:BM6),0) -> 3.7351259 | BO4: =MAX(D4:BM6) -> 11.8
B5: 0 REFERENCE | C5: C | D5: 0.414 | E5: 3.45 | F5: 4.07 | G5: 3.78 | H5: 2.34 | I5: ND | J5: ND | K5: 1.18 | L5: 2.88 | M5: 9.16 | N5: 6.28 | O5: ND | P5: 6.6 | Q5: 1.57 | R5: 4.52 | S5: 5.17 | T5: 3.97 | U5: 6.25 | V5: 5.13 | W5: 3.61 | X5: 1.57 | Y5: 2 | Z5: 5.21 | AA5: 0.955 | AB5: 1.52 | AC5: 3.67 | AD5: 4.92 | AE5: ND | AF5: 2.8 | AG5: 6.6 | AH5: 2.55 | AI5: 4.96 | AJ5: 6.84 | AK5: 2.29 | AL5: 4.38 | AM5: 5.75 | AN5: ND | AO5: 6.28 | AP5: ND | AQ5: ND | AR5: 7.9 | AS5: 5.16 | AT5: 6.96 | AU5: 4.31 | AV5: ND | AW5: ND | AX5: 1.39 | AY5: ND | AZ5: 3.61 | BA5: 5 | BB5: 3.17 | BC5: 5.07 | BD5: 4.53 | BE5: ND | BF5: 4.29 | BG5: 3.32 | BH5: 2.63 | BI5: ND | BJ5: 2.78 | BK5: 3.72 | BL5: 0.617 | BM5: 3.74 | BN5: =IFERROR(AVERAGE(D5:BM7),0) -> 3.9508333 | BO5: =MAX(D5:BM7) -> 12.2
C6: R | D6: ND | E6: ND | F6: 4.27 | G6: 4.36 | H6: 0.198 | I6: 0.954 | J6: ND | K6: 0.47 | L6: 4.53 | M6: 2.6 | N6: ND | O6: ND | P6: 3.36 | Q6: ND | R6: 5.76 | S6: 6.48 | T6: ND | U6: ND | V6: 4.1 | W6: ND | X6: 6.31 | Y6: 3.59 | Z6: 1.89 | AA6: ND | AB6: 2.72 | AC6: 0.829 | AD6: 3 | AE6: 4.06 | AF6: 0.515 | AG6: 3.16 | AH6: 2.61 | AI6: ND | AJ6: 0.648 | AK6: 4.05 | AL6: 0.231 | AM6: 1.83 | AN6: ND | AO6: 5.34 | AP6: ND | AQ6: 0.674 | AR6: 3.76 | AS6: 6.69 | AT6: 3.33 | AU6: 6.05 | AV6: ND | AW6: 0.911 | AX6: 1.87 | AY6: 1.36 | AZ6: 4.98 | BA6: 2.96 | BB6: 4.28 | BC6: 8.46 | BD6: 0.06 | BE6: 3.1 | BF6: ND | BG6: 1.42 | BH6: 3.28 | BI6: ND | BJ6: ND | BK6: ND | BL6: 5.41 | BM6: 3.6 | BN6: =IFERROR(AVERAGE(D6:BM8),0) -> 4.0200252 | BO6: =MAX(D6:BM8) -> 12.2
A7: A | C7: L | D7: 1.73 | E7: ND | F7: 2.75 | G7: ND | H7: 1.91 | I7: 0.899 | J7: 2.66 | K7: 4.75 | L7: 1.4 | M7: 5.67 | N7: 3.06 | O7: 8.49 | P7: 3.46 | Q7: 4.53 | R7: 2.33 | S7: 5.39 | T7: 4.06 | U7: 4.97 | V7: 3.51 | W7: 5.19 | X7: 3.42 | Y7: 3.58 | Z7: 4.09 | AA7: 2.04 | AB7: 3.99 | AC7: ND | AD7: ND | AE7: 1.36 | AF7: 4.81 | AG7: 3.86 | AH7: 4.97 | AI7: ND | AJ7: 4.63 | AK7: 3.28 | AL7: ND | AM7: 2.33 | AN7: 4.23 | AO7: 4.89 | AP7: 6.77 | AQ7: 4.31 | AR7: 4.37 | AS7: 5.23 | AT7: 4.75 | AU7: 5.41 | AV7: 5.13 | AW7: 3.2 | AX7: 8.14 | AY7: 4.15 | AZ7: 6.68 | BA7: 6.5 | BB7: 7.96 | BC7: 3.7 | BD7: 4.81 | BE7: 7.17 | BF7: 4.6 | BG7: 3.83 | BH7: 6.62 | BI7: 7.89 | BJ7: 1.32 | BK7: 2.16 | BL7: 12.2 | BM7: 6.56 | BN7: =IFERROR(AVERAGE(D7:BM9),0) -> 4.2418721 | BO7: =MAX(D7:BM9) -> 12.2
B8: -6 FEET | C8: C | D8: 3.6 | E8: 4.66 | F8: 4.67 | G8: ND | H8: 3.96 | I8: 3.09 | J8: 1.27 | K8: 2.37 | L8: 3.62 | M8: 3.26 | N8: 5.53 | O8: 3.52 | P8: 6.77 | Q8: 2.92 | R8: 0.882 | S8: 0.418 | T8: 2.43 | U8: 6.24 | V8: 4.65 | W8: 6.28 | X8: 4 | Y8: 4.34 | Z8: 1.63 | AA8: 3.38 | AB8: 4.02 | AC8: 2 | AD8: ND | AE8: 0.305 | AF8: 6.31 | AG8: 5.79 | AH8: 2.12 | AI8: 4.88 | AJ8: 7.47 | AK8: 2.16 | AL8: 1.44 | AM8: 1.45 | AN8: 5.35 | AO8: 4.31 | AP8: ND | AQ8: 3.42 | AR8: 2.19 | AS8: 2.55 | AT8: 4.31 | AU8: 2.3 | AV8: 4.67 | AW8: 5.28 | AX8: 7.55 | AY8: 6.01 | AZ8: 3.98 | BA8: 7.09 | BB8: 3.39 | BC8: 2.44 | BD8: 4.25 | BE8: 7.33 | BF8: 6.65 | BG8: 5.23 | BH8: 8.51 | BI8: 4.77 | BJ8: 1.83 | BK8: 3.36 | BL8: 10.6 | BM8: 8.62 | BN8: =IFERROR(AVERAGE(D8:BM10),0) -> 3.9227836 | BO8: =MAX(D8:BM10) -> 10.6
C9: R | D9: 1.74 | E9: ND | F9: 1.66 | G9: 6.27 | H9: 1.86 | I9: 2.28 | J9: 1.79 | K9: 3.05 | L9: 1.73 | M9: 3.17 | N9: 3.37 | O9: 2.43 | P9: 5.29 | Q9: 3.61 | R9: 6.59 | S9: 0.323 | T9: 3.97 | U9: 1.52 | V9: 5.89 | W9: ND | X9: 1.61 | Y9: 3.75 | Z9: 5.7 | AA9: 1.77 | AB9: 2.98 | AC9: 2.32 | AD9: 0.245 | AE9: 3.5 | AF9: ND | AG9: 5.6 | AH9: 4 | AI9: 3.44 | AJ9: 2.55 | AK9: 4.12 | AL9: 3.06 | AM9: 4.3 | AN9: 6.08 | AO9: 7.16 | AP9: ND | AQ9: 2.19 | AR9: 2.98 | AS9: 5.09 | AT9: 3.6 | AU9: 3.69 | AV9: 4.26 | AW9: 1.71 | AX9: 8.27 | AY9: 3.97 | AZ9: 6.26 | BA9: ND | BB9: 3.12 | BC9: 5.46 | BD9: 6.85 | BE9: 6.08 | BF9: 7.59 | BG9: 4.62 | BH9: 7.96 | BI9: 6.59 | BJ9: 5 | BK9: 7.79 | BL9: 7.47 | BM9: 1.2 | BN9: =IFERROR(AVERAGE(D9:BM11),0) -> 3.8403354 | BO9: =MAX(D9:BM11) -> 13.9
A10: A | C10: L | D10: ND | E10: ND | F10: 5.12 | G10: 3.02 | H10: 0.926 | I10: 3.63 | J10: ND | K10: ND | L10: 3.62 | M10: 3.08 | N10: 2.06 | O10: 0.368 | P10: 3.22 | Q10: 1.96 | R10: 0.665 | S10: 6.05 | T10: 3.84 | U10: 0.287 | V10: 4.67 | W10: 1.97 | X10: ND | Y10: ND | Z10: 5.18 | AA10: 2.7 | AB10: 2.61 | AC10: 4.7 | AD10: 3.72 | AE10: 3.51 | AF10: 1.9 | AG10: 3.77 | AH10: 2.02 | AI10: 3.47 | AJ10: 4.71 | AK10: 7.69 | AL10: ND | AM10: 2.68 | AN10: 4.51 | AO10: 2.72 | AP10: 3.81 | AQ10: 1.05 | AR10: 2.04 | AS10: 1.89 | AT10: 5.28 | AU10: 3.29 | AV10: 4.13 | AW10: 2.28 | AX10: 5.19 | AY10: 1.1 | AZ10: 4.74 | BA10: 2.29 | BB10: 4.62 | BC10: 3.53 | BD10: 3.21 | BE10: 0.917 | BF10: 5.39 | BG10: 3.76 | BH10: 7.18 | BI10: 1.76 | BJ10: 5.39 | BK10: 6.67 | BL10: 3.02 | BM10: 9.98 | BN10: =IFERROR(AVERAGE(D10:BM12),0) -> 3.9886646 | BO10: =MAX(D10:BM12) -> 13.9
B11: -12 FEET | C11: C | D11: ND | E11: 5.07 | F11: 0.051 | G11: 4.38 | H11: ND | I11: ND | J11: ND | K11: 12.3 | L11: 7.63 | M11: 3.67 | N11: 1.94 | O11: 0.264 | P11: 0.527 | Q11: 3.14 | R11: 5.53 | S11: 1.1 | T11: ND | U11: 0.585 | V11: 2.03 | W11: 2.86 | X11: ND | Y11: 5.81 | Z11: 6.82 | AA11: 0.864 | AB11: 5.31 | AC11: 4.41 | AD11: 3.82 | AE11: 2.31 | AF11: 0.89 | AG11: 1.89 | AH11: 2.59 | AI11: ND | AJ11: 2.87 | AK11: 6.83 | AL11: 3.12 | AM11: 3.25 | AN11: ND | AO11: 5.77 | AP11: 1.25 | AQ11: ND | AR11: 0.325 | AS11: 1.25 | AT11: 0.308 | AU11: 2.48 | AV11: ND | AW11: 8.55 | AX11: 1.27 | AY11: 2.27 | AZ11: 5.43 | BA11: 1.49 | BB11: 5.73 | BC11: 6.35 | BD11: 5.03 | BE11: 5.73 | BF11: 9.97 | BG11: 4.22 | BH11: 1.38 | BI11: 5.3 | BJ11: 1.54 | BK11: 4.84 | BL11: 10.2 | BM11: 13.9 | BN11: =IFERROR(AVERAGE(D11:BM13),0) -> 4.5477582 | BO11: =MAX(D11:BM13) -> 13.9
C12: R | D12: 3.18 | E12: 3.14 | F12: 6.84 | G12: 6.61 | H12: 0.379 | I12: ND | J12: ND | K12: ND | L12: 3.91 | M12: 1.91 | N12: 2.54 | O12: 2.13 | P12: 2.62 | Q12: 3.49 | R12: ND | S12: 2.7 | T12: 2.52 | U12: 7.59 | V12: 7.01 | W12: 4.29 | X12: 2.1 | Y12: 2.56 | Z12: 3.4 | AA12: 6.75 | AB12: 7.44 | AC12: 11.5 | AD12: 9.33 | AE12: 2.65 | AF12: 1.29 | AG12: 3.85 | AH12: 0.991 | AI12: 0.573 | AJ12: 2.11 | AK12: ND | AL12: 7.8 | AM12: 3.91 | AN12: 1.86 | AO12: ND | AP12: 6.61 | AQ12: 1.66 | AR12: ND | AS12: 3.61 | AT12: 2.72 | AU12: 0.375 | AV12: 3.92 | AW12: 1.52 | AX12: 5.94 | AY12: 1.76 | AZ12: 3.46 | BA12: ND | BB12: 6.38 | BC12: 4.96 | BD12: 6.48 | BE12: 3.7 | BF12: 9.44 | BG12: 8.09 | BH12: 7.42 | BI12: 4.39 | BJ12: 6.64 | BK12: 6.44 | BL12: 5.75 | BM12: 12.6 | BN12: =IFERROR(AVERAGE(D12:BM14),0) -> 5.2360204 | BO12: =MAX(D12:BM14) -> 16.4
A13: A | C13: L | D13: 10.6 | E13: 13.5 | F13: 4.82 | G13: 2.57 | H13: 6.55 | I13: 5.52 | J13: 3.07 | K13: 1.42 | L13: 4.39 | M13: 8.15 | N13: ND | O13: 13.8 | P13: 4.5 | Q13: 11.8 | R13: ND | S13: 8.49 | T13: ND | U13: 4.84 | V13: 4.84 | W13: 0.565 | X13: ND | Y13: ND | Z13: 5.7 | AA13: 5.3 | AB13: 5.01 | AC13: 1.2 | AD13: ND | AE13: 5.41 | AF13: ND | AG13: 1.88 | AH13: ND | AI13: ND | AJ13: 2.25 | AK13: ND | AL13: 3.65 | AM13: 4.44 | AN13: 3.85 | AO13: 3.85 | AP13: 5.78 | AQ13: 5.02 | AR13: 5.81 | AS13: 4.67 | AT13: 4.16 | AU13: 6.21 | AV13: 7.75 | AW13: 3.02 | AX13: 4.49 | AY13: 10 | AZ13: ND | BA13: 6.38 | BB13: 3.47 | BC13: 8.33 | BD13: 1.92 | BE13: ND | BF13: 3.85 | BG13: 0.279 | BH13: 0.111 | BI13: 2.11 | BJ13: 11.2 | BK13: ND | BL13: ND | BM13: ND | BN13: =IFERROR(AVERAGE(D13:BM15),0) -> 5.5170552 | BO13: =MAX(D13:BM15) -> 16.4
B14: -18 FEET | C14: C | D14: 10.6 | E14: 13.1 | F14: 2.25 | G14: 1.28 | H14: 5.42 | I14: 9.69 | J14: ND | K14: 5.81 | L14: 5.07 | M14: 5.75 | N14: 1.94 | O14: 12.8 | P14: 9 | Q14: 10.9 | R14: 4.61 | S14: 4.05 | T14: ND | U14: 2.85 | V14: ND | W14: 2.79 | X14: ND | Y14: 6.04 | Z14: ND | AA14: 3.36 | AB14: ND | AC14: 3.65 | AD14: 0.628 | AE14: 0.684 | AF14: ND | AG14: 3.93 | AH14: ND | AI14: ND | AJ14: ND | AK14: ND | AL14: 5.12 | AM14: ND | AN14: 2.25 | AO14: 4.18 | AP14: 5.14 | AQ14: ND | AR14: 4.04 | AS14: ND | AT14: 4.78 | AU14: 8.32 | AV14: 4.5 | AW14: 1.65 | AX14: 9.69 | AY14: 2.11 | AZ14: 5.3 | BA14: 8.43 | BB14: 5.87 | BC14: 16.4 | BD14: 2.57 | BE14: 10.2 | BF14: 11.8 | BG14: 10.4 | BH14: 8.6 | BI14: 6.55 | BJ14: 12.7 | BK14: 3.53 | BL14: ND | BM14: ND | BN14: =IFERROR(AVERAGE(D14:BM16),0) -> 15.6653 | BO14: =MAX(D14:BM16) -> 62
C15: R | D15: ND | E15: 9.32 | F15: 0.643 | G15: 0.643 | H15: 4.9 | I15: 4.9 | J15: 6.75 | K15: 5.98 | L15: 9.12 | M15: 4.73 | N15: 8.21 | O15: 7.39 | P15: 9 | Q15: 7.39 | R15: 2.45 | S15: 2.96 | T15: ND | U15: 7.7 | V15: 3.3 | W15: 6.5 | X15: 7.92 | Y15: 5.64 | Z15: 3.07 | AA15: 1.76 | AB15: 2.05 | AC15: 4.79 | AD15: 1.42 | AE15: 7.41 | AF15: 5.41 | AG15: ND | AH15: ND | AI15: 8.32 | AJ15: 2.89 | AK15: 0.74 | AL15: ND | AM15: 4.04 | AN15: 5.14 | AO15: 6.75 | AP15: 8.03 | AQ15: ND | AR15: ND | AS15: 3.42 | AT15: 4.21 | AU15: 9.12 | AV15: 3.53 | AW15: 4.21 | AX15: 6.27 | AY15: 5.98 | AZ15: 2.73 | BA15: 5.93 | BB15: 4.79 | BC15: 6.5 | BD15: 4.18 | BE15: 4.82 | BF15: 7.71 | BG15: 6.84 | BH15: 3.07 | BI15: 3.02 | BJ15: 9.52 | BK15: ND | BL15: ND | BM15: ND | BN15: =IFERROR(AVERAGE(D15:BM17),0) -> 19.527333 | BO15: =MAX(D15:BM17) -> 62
A16: ELEVATION | C16: LOC | D16: 1 | E16: 2 | F16: 3 | G16: 4 | H16: 5 | I16: 6 | J16: 7 | K16: 8 | L16: 9 | M16: 10 | N16: 11 | O16: 12 | P16: 13 | Q16: 14 | R16: 15 | S16: 16 | T16: 17 | U16: 18 | V16: 19 | W16: 20 | X16: 21 | Y16: 22 | Z16: 23 | AA16: 24 | AB16: 25 | AC16: 26 | AD16: 27 | AE16: 28 | AF16: 29 | AG16: 30 | AH16: 31 | AI16: 32 | AJ16: 33 | AK16: 34 | AL16: 35 | AM16: 36 | AN16: 37 | AO16: 38 | AP16: 39 | AQ16: 40 | AR16: 41 | AS16: 42 | AT16: 43 | AU16: 44 | AV16: 45 | AW16: 46 | AX16: 47 | AY16: 48 | AZ16: 49 | BA16: 50 | BB16: 51 | BC16: 52 | BD16: 53 | BE16: 54 | BF16: 55 | BG16: 56 | BH16: 57 | BI16: 58 | BJ16: 59 | BK16: 60 | BL16: 61 | BM16: 62 | BN16: AVG | BO16: MAX
B97: CORROSION RATE (mpy): | M97: NOTE: CORROSION RATES ARE BASED ON COMPARISON OF | AG97: TEST RESULTS | BR97: APPLIED TECHNICAL SERVICES 1049 Triad Court Marietta, Georgia 30062 Office # (770) 423-1400 Fax # (770) 514-3299 www.atslab.com | CL97: =Thickness!CL97 -> INTERNATIONAL PAPER
A98: LEGEND | B98: < 0 mpy (LOSS) or no data | AG98: OVERALL CORROSION RATE (mils per year): | CL98: =Thickness!CL98 -> RIVERDALE MILL
B99: 0-10 mpy (LOSS) | M99: 2020, 2022, 2023, 2024, 2025 | CL99: CALCULATED CORROSION RATE
B100: 10-20 mpy (LOSS) | M100: INSPECTION DATA | AG100: 4.363 | CL100: =Thickness!CL100 -> NO. 1 RECOVERY BOILER
B101: > 20 mpy (LOSS) | M101: ND | R101: NO COMPARISON DATA | AW101: =Thickness!AW101 -> Job # H449364 P.O. # 0018342455 W.O. # N/A Date: 5/05/2025 | CL101: =Thickness!CL101 -> 01 FLOOR
B102: CORROSION
BR105: APPLIED TECHNICAL SERVICES 1049 Triad Court Marietta, Georgia 30062 Office # (770) 423-1400 Fax # (770) 514-3299 www.atslab.com
BR110: APPLIED TECHNICAL SERVICES 1325-B Cavalier Boulevard Chesapeake, Virginia 23323 (757) 558-0016 Fax (757) 558-0063 www.atslab.com
BR115: APPLIED TECHNICAL SERVICES 2312 Commerce Ctr. Dr., Suite A Rockville, Virginia 23146 (804) 550-7610 Fax (804) 550-7611 www.atslab.com

Sheet Projection
A1: =Thickness!A1 -> 2025 | C1: =IF(ISBLANK(Thickness!C1),"",(Thickness!C1)) -> NC - NOT CLEAN; | DQ1: OBSTRUCTION
C2: TUBES NUMBERED LEFT TO RIGHT FACING WALL. PROJECTED THICKNESS MEASUREMENTS ARE IN INCHES. | DQ2: ORIENTATION
A3: ELEVATION | C3: LOC | D3: 1 | E3: 2 | F3: 3 | G3: 4 | H3: 5 | I3: 6 | J3: 7 | K3: 8 | L3: 9 | M3: 10 | N3: 11 | O3: 12 | P3: 13 | Q3: 14 | R3: 15 | S3: 16 | T3: 17 | U3: 18 | V3: 19 | W3: 20 | X3: 21 | Y3: 22 | Z3: 23 | AA3: 24 | AB3: 25 | AC3: 26 | AD3: 27 | AE3: 28 | AF3: 29 | AG3: 30 | AH3: 31 | AI3: 32 | AJ3: 33 | AK3: 34 | AL3: 35 | AM3: 36 | AN3: 37 | AO3: 38 | AP3: 39 | AQ3: 40 | AR3: 41 | AS3: 42 | AT3: 43 | AU3: 44 | AV3: 45 | AW3: 46 | AX3: 47 | AY3: 48 | AZ3: 49 | BA3: 50 | BB3: 51 | BC3: 52 | BD3: 53 | BE3: 54 | BF3: 55 | BG3: 56 | BH3: 57 | BI3: 58 | BJ3: 59 | BK3: 60 | BL3: 61 | BM3: 62 | BN3: AVG | BO3: MIN
A4: A | C4: L | D4: 0.334 | E4: 0.34 | F4: 0.324 | G4: 0.307 | H4: 0.337 | I4: 0.351 | J4: 0.344 | K4: 0.335 | L4: 0.352 | M4: 0.345 | N4: 0.322 | O4: 0.342 | P4: 0.308 | Q4: 0.372 | R4: 0.322 | S4: 0.304 | T4: 0.247 | U4: 0.364 | V4: 0.286 | W4: 0.288 | X4: 0.316 | Y4: 0.278 | Z4: 0.32 | AA4: 0.318 | AB4: 0.328 | AC4: 0.336 | AD4: 0.328 | AE4: 0.328 | AF4: 0.299 | AG4: 0.319 | AH4: 0.324 | AI4: 0.324 | AJ4: 0.303 | AK4: 0.347 | AL4: 0.358 | AM4: 0.312 | AN4: 0.319 | AO4: 0.288 | AP4: 0.273 | AQ4: 0.362 | AR4: 0.316 | AS4: 0.315 | AT4: 0.282 | AU4: 0.293 | AV4: 0.347 | AW4: 0.32 | AX4: 0.341 | AY4: 0.324 | AZ4: 0.313 | BA4: 0.311 | BB4: 0.314 | BC4: 0.312 | BD4: 0.309 | BE4: 0.331 | BF4: 0.394 | BG4: 0.307 | BH4: 0.32 | BI4: 0.318 | BJ4: 0.339 | BK4: 0.353 | BL4: 0.322 | BM4: 0.344 | BN4: =IFERROR(AVERAGE(D4:BM6),0) -> 0.32499462 | BO4: =MIN(D4:BM6) -> 0.247
A5: 0.083 | B5: 0 REFERENCE | C5: C | D5: 0.352 | E5: 0.326 | F5: 0.327 | G5: 0.322 | H5: 0.344 | I5: 0.357 | J5: 0.359 | K5: 0.331 | L5: 0.328 | M5: 0.282 | N5: 0.281 | O5: 0.351 | P5: 0.288 | Q5: 0.321 | R5: 0.307 | S5: 0.302 | T5: 0.309 | U5: 0.293 | V5: 0.295 | W5: 0.313 | X5: 0.321 | Y5: 0.323 | Z5: 0.296 | AA5: 0.333 | AB5: 0.326 | AC5: 0.316 | AD5: 0.313 | AE5: 0.353 | AF5: 0.308 | AG5: 0.279 | AH5: 0.312 | AI5: 0.302 | AJ5: 0.294 | AK5: 0.325 | AL5: 0.301 | AM5: 0.306 | AN5: 0.332 | AO5: 0.287 | AP5: 0.362 | AQ5: 0.327 | AR5: 0.288 | AS5: 0.297 | AT5: 0.289 | AU5: 0.302 | AV5: 0.363 | AW5: 0.334 | AX5: 0.321 | AY5: 0.335 | AZ5: 0.313 | BA5: 0.303 | BB5: 0.324 | BC5: 0.308 | BD5: 0.304 | BE5: 0.355 | BF5: 0.329 | BG5: 0.337 | BH5: 0.338 | BI5: 0.395 | BJ5: 0.338 | BK5: 0.326 | BL5: 0.357 | BM5: 0.327 | BN5: =IFERROR(AVERAGE(D5:BM7),0) -> 0.315 | BO5: =MIN(D5:BM7) -> 0.241
C6: R | D6: 0.393 | E6: 0.385 | F6: 0.322 | G6: 0.313 | H6: 0.362 | I6: 0.349 | J6: 0.359 | K6: 0.334 | L6: 0.311 | M6: 0.33 | N6: 0.356 | O6: 0.352 | P6: 0.308 | Q6: 0.343 | R6: 0.29 | S6: 0.288 | T6: 0.357 | U6: 0.347 | V6: 0.312 | W6: 0.355 | X6: 0.287 | Y6: 0.325 | Z6: 0.333 | AA6: 0.337 | AB6: 0.325 | AC6: 0.33 | AD6: 0.323 | AE6: 0.307 | AF6: 0.333 | AG6: 0.3 | AH6: 0.317 | AI6: 0.358 | AJ6: 0.338 | AK6: 0.303 | AL6: 0.337 | AM6: 0.317 | AN6: 0.349 | AO6: 0.304 | AP6: 0.336 | AQ6: 0.33 | AR6: 0.318 | AS6: 0.291 | AT6: 0.314 | AU6: 0.29 | AV6: 0.352 | AW6: 0.328 | AX6: 0.317 | AY6: 0.332 | AZ6: 0.314 | BA6: 0.319 | BB6: 0.314 | BC6: 0.277 | BD6: 0.343 | BE6: 0.312 | BF6: 0.391 | BG6: 0.35 | BH6: 0.331 | BI6: 0.398 | BJ6: 0.373 | BK6: 0.367 | BL6: 0.32 | BM6: 0.327 | BN6: =IFERROR(AVERAGE(D6:BM8),0) -> 0.3058 | BO6: =MIN(D6:BM8) -> 0.241
A7: A | C7: L | D7: 0.322 | E7: NC | F7: 0.309 | G7: 0.359 | H7: 0.314 | I7: 0.321 | J7: 0.309 | K7: 0.288 | L7: 0.317 | M7: 0.266 | N7: 0.29 | O7: 0.252 | P7: 0.28 | Q7: 0.282 | R7: 0.302 | S7: 0.273 | T7: 0.289 | U7: 0.288 | V7: 0.295 | W7: 0.283 | X7: 0.297 | Y7: 0.31 | Z7: 0.291 | AA7: 0.317 | AB7: 0.295 | AC7: 0.333 | AD7: 0.338 | AE7: 0.309 | AF7: 0.287 | AG7: 0.297 | AH7: 0.287 | AI7: 0.324 | AJ7: 0.29 | AK7: 0.297 | AL7: 0.323 | AM7: 0.301 | AN7: 0.284 | AO7: 0.288 | AP7: 0.272 | AQ7: 0.294 | AR7: 0.284 | AS7: 0.294 | AT7: 0.285 | AU7: 0.278 | AV7: 0.277 | AW7: 0.293 | AX7: 0.265 | AY7: 0.285 | AZ7: 0.257 | BA7: 0.27 | BB7: 0.256 | BC7: 0.288 | BD7: 0.286 | BE7: 0.269 | BF7: 0.289 | BG7: 0.291 | BH7: 0.281 | BI7: 0.278 | BJ7: 0.321 | BK7: 0.317 | BL7: 0.241 | BM7: 0.277 | BN7: =IFERROR(AVERAGE(D7:BM9),0) -> 0.29438378 | BO7: =MIN(D7:BM9) -> 0.241
A8: 0.083 | B8: -6 FEET | C8: C | D8: 0.308 | E8: 0.292 | F8: 0.302 | G8: 0.361 | H8: 0.292 | I8: 0.301 | J8: 0.318 | K8: 0.3 | L8: 0.284 | M8: 0.285 | N8: 0.263 | O8: 0.287 | P8: 0.26 | Q8: 0.295 | R8: 0.315 | S8: 0.316 | T8: 0.309 | U8: 0.277 | V8: 0.287 | W8: 0.27 | X8: 0.297 | Y8: 0.296 | Z8: 0.299 | AA8: 0.302 | AB8: 0.295 | AC8: 0.306 | AD8: 0.341 | AE8: 0.322 | AF8: 0.279 | AG8: 0.279 | AH8: 0.312 | AI8: 0.29 | AJ8: 0.273 | AK8: 0.305 | AL8: 0.307 | AM8: 0.306 | AN8: 0.292 | AO8: 0.285 | AP8: 0.319 | AQ8: 0.3 | AR8: 0.3 | AS8: 0.296 | AT8: 0.282 | AU8: 0.3 | AV8: 0.277 | AW8: 0.285 | AX8: 0.267 | AY8: 0.274 | AZ8: 0.284 | BA8: 0.266 | BB8: 0.296 | BC8: 0.292 | BD8: 0.288 | BE8: 0.264 | BF8: 0.28 | BG8: 0.289 | BH8: 0.269 | BI8: 0.301 | BJ8: 0.315 | BK8: 0.315 | BL8: 0.25 | BM8: 0.268 | BN8: =IFERROR(AVERAGE(D8:BM10),0) -> 0.29697283 | BO8: =MIN(D8:BM10) -> 0.245
C9: R | D9: 0.334 | E9: 0.337 | F9: 0.314 | G9: 0.278 | H9: 0.313 | I9: 0.305 | J9: 0.312 | K9: 0.293 | L9: 0.298 | M9: 0.287 | N9: 0.283 | O9: 0.293 | P9: 0.275 | Q9: 0.287 | R9: 0.275 | S9: 0.315 | T9: 0.301 | U9: 0.308 | V9: 0.283 | W9: 0.319 | X9: 0.319 | Y9: 0.296 | Z9: 0.28 | AA9: 0.315 | AB9: 0.305 | AC9: 0.309 | AD9: 0.323 | AE9: 0.294 | AF9: 0.356 | AG9: 0.287 | AH9: 0.298 | AI9: 0.301 | AJ9: 0.31 | AK9: 0.292 | AL9: 0.305 | AM9: 0.293 | AN9: 0.275 | AO9: 0.277 | AP9: 0.35 | AQ9: 0.307 | AR9: 0.302 | AS9: 0.286 | AT9: 0.295 | AU9: 0.291 | AV9: 0.288 | AW9: 0.309 | AX9: 0.257 | AY9: 0.287 | AZ9: 0.266 | BA9: 0.339 | BB9: 0.296 | BC9: 0.275 | BD9: 0.268 | BE9: 0.279 | BF9: 0.277 | BG9: 0.29 | BH9: 0.265 | BI9: 0.284 | BJ9: 0.295 | BK9: 0.263 | BL9: 0.275 | BM9: 0.332 | BN9: =IFERROR(AVERAGE(D9:BM11),0) -> 0.29727869 | BO9: =MIN(D9:BM11) -> 0.206
A10: A | C10: L | D10: NC | E10: NC | F10: 0.286 | G10: 0.297 | H10: 0.316 | I10: 0.301 | J10: 0.389 | K10: 0.355 | L10: 0.299 | M10: 0.29 | N10: 0.298 | O10: 0.315 | P10: 0.292 | Q10: 0.297 | R10: 0.313 | S10: 0.269 | T10: 0.298 | U10: 0.32 | V10: 0.289 | W10: 0.297 | X10: 0.36 | Y10: 0.33 | Z10: 0.283 | AA10: 0.29 | AB10: 0.306 | AC10: 0.297 | AD10: 0.29 | AE10: 0.297 | AF10: 0.312 | AG10: 0.302 | AH10: 0.307 | AI10: 0.298 | AJ10: 0.289 | AK10: 0.269 | AL10: 0.354 | AM10: 0.299 | AN10: 0.296 | AO10: 0.305 | AP10: 0.288 | AQ10: 0.319 | AR10: 0.304 | AS10: 0.31 | AT10: 0.296 | AU10: 0.297 | AV10: 0.297 | AW10: 0.296 | AX10: 0.274 | AY10: 0.308 | AZ10: 0.296 | BA10: 0.306 | BB10: 0.279 | BC10: 0.297 | BD10: 0.296 | BE10: 0.304 | BF10: 0.288 | BG10: 0.298 | BH10: 0.265 | BI10: 0.317 | BJ10: 0.283 | BK10: 0.272 | BL10: 0.297 | BM10: 0.245 | BN10: =IFERROR(AVERAGE(D10:BM12),0) -> 0.29697814 | BO10: =MIN(D10:BM12) -> 0.206
A11: 0.083 | B11: -12 FEET | C11: C | D11: NC | E11: 0.288 | F11: 0.337 | G11: 0.286 | H11: 0.323 | I11: 0.348 | J11: 0.381 | K11: 0.222 | L11: 0.268 | M11: 0.297 | N11: 0.295 | O11: 0.316 | P11: 0.307 | Q11: 0.294 | R11: 0.278 | S11: 0.314 | T11: 0.334 | U11: 0.306 | V11: 0.301 | W11: 0.283 | X11: 0.33 | Y11: 0.274 | Z11: 0.27 | AA11: 0.307 | AB11: 0.279 | AC11: 0.293 | AD11: 0.29 | AE11: 0.302 | AF11: 0.322 | AG11: 0.303 | AH11: 0.298 | AI11: 0.33 | AJ11: 0.309 | AK11: 0.268 | AL11: 0.298 | AM11: 0.286 | AN11: 0.319 | AO11: 0.274 | AP11: 0.307 | AQ11: 0.334 | AR11: 0.323 | AS11: 0.31 | AT11: 0.314 | AU11: 0.296 | AV11: 0.32 | AW11: 0.259 | AX11: 0.309 | AY11: 0.301 | AZ11: 0.275 | BA11: 0.297 | BB11: 0.258 | BC11: 0.253 | BD11: 0.266 | BE11: 0.261 | BF11: 0.241 | BG11: 0.279 | BH11: 0.302 | BI11: 0.266 | BJ11: 0.307 | BK11: 0.286 | BL11: 0.244 | BM11: 0.206 | BN11: =IFERROR(AVERAGE(D11:BM13),0) -> 0.29221765 | BO11: =MIN(D11:BM13) -> 0.204
C12: R | D12: 0.319 | E12: 0.318 | F12: 0.28 | G12: 0.27 | H12: 0.32 | I12: 0.353 | J12: 0.383 | K12: 0.345 | L12: 0.291 | M12: 0.299 | N12: 0.294 | O12: 0.304 | P12: 0.297 | Q12: 0.292 | R12: 0.326 | S12: 0.299 | T12: 0.312 | U12: 0.264 | V12: 0.267 | W12: 0.291 | X12: 0.308 | Y12: 0.309 | Z12: 0.291 | AA12: 0.271 | AB12: 0.27 | AC12: 0.236 | AD12: 0.256 | AE12: 0.301 | AF12: 0.314 | AG12: 0.3 | AH12: 0.313 | AI12: 0.322 | AJ12: 0.306 | AK12: 0.355 | AL12: 0.269 | AM12: 0.292 | AN12: 0.309 | AO12: 0.38 | AP12: 0.271 | AQ12: 0.312 | AR12: 0.332 | AS12: 0.302 | AT12: 0.295 | AU12: 0.321 | AV12: 0.298 | AW12: 0.303 | AX12: 0.282 | AY12: 0.304 | AZ12: 0.294 | BA12: 0.32 | BB12: 0.271 | BC12: 0.277 | BD12: 0.26 | BE12: 0.286 | BF12: 0.25 | BG12: 0.267 | BH12: 0.265 | BI12: 0.287 | BJ12: 0.27 | BK12: 0.275 | BL12: 0.275 | BM12: 0.223 | BN12: =IFERROR(AVERAGE(D12:BM14),0) -> 0.28597419 | BO12: =MIN(D12:BM14) -> 0.17
A13: A | C13: L | D13: 0.244 | E13: 0.22 | F13: 0.286 | G13: 0.325 | H13: 0.282 | I13: 0.285 | J13: 0.308 | K13: 0.327 | L13: 0.292 | M13: 0.26 | N13: NC | O13: 0.204 | P13: 0.275 | Q13: 0.218 | R13: NC | S13: 0.258 | T13: NC | U13: 0.3 | V13: 0.295 | W13: 0.327 | X13: NC | Y13: NC | Z13: 0.284 | AA13: 0.294 | AB13: 0.288 | AC13: 0.326 | AD13: NC | AE13: 0.286 | AF13: NC | AG13: 0.314 | AH13: NC | AI13: NC | AJ13: 0.317 | AK13: NC | AL13: 0.293 | AM13: 0.291 | AN13: 0.28 | AO13: 0.302 | AP13: 0.278 | AQ13: 0.287 | AR13: 0.288 | AS13: 0.288 | AT13: 0.292 | AU13: 0.277 | AV13: 0.259 | AW13: 0.302 | AX13: 0.293 | AY13: 0.234 | AZ13: NC | BA13: 0.274 | BB13: 0.296 | BC13: 0.248 | BD13: 0.302 | BE13: NC | BF13: 0.284 | BG13: 0.326 | BH13: 0.321 | BI13: 0.31 | BJ13: 0.227 | BK13: NC | BL13: NC | BM13: NC | BN13: =IFERROR(AVERAGE(D13:BM15),0) -> 0.28068276 | BO13: =MIN(D13:BM15) -> 0.17
A14: 0.083 | B14: -18 FEET | C14: C | D14: 0.251 | E14: 0.221 | F14: 0.311 | G14: 0.321 | H14: 0.277 | I14: 0.254 | J14: NC | K14: 0.274 | L14: 0.276 | M14: 0.279 | N14: 0.315 | O14: 0.208 | P14: 0.235 | Q14: 0.218 | R14: 0.281 | S14: 0.297 | T14: NC | U14: 0.307 | V14: NC | W14: 0.305 | X14: NC | Y14: 0.28 | Z14: NC | AA14: 0.302 | AB14: NC | AC14: 0.295 | AD14: 0.328 | AE14: 0.334 | AF14: NC | AG14: 0.299 | AH14: NC | AI14: NC | AJ14: NC | AK14: NC | AL14: 0.288 | AM14: NC | AN14: 0.299 | AO14: 0.281 | AP14: 0.282 | AQ14: NC | AR14: 0.304 | AS14: NC | AT14: 0.288 | AU14: 0.251 | AV14: 0.286 | AW14: 0.314 | AX14: 0.247 | AY14: 0.305 | AZ14: 0.284 | BA14: 0.248 | BB14: 0.27 | BC14: 0.17 | BD14: 0.296 | BE14: 0.231 | BF14: 0.21 | BG14: 0.234 | BH14: 0.252 | BI14: 0.27 | BJ14: 0.212 | BK14: 0.303 | BL14: NC | BM14: NC | BN14: =IFERROR(AVERAGE(D14:BM16),0) -> 12.377075 | BO14: =MIN(D14:BM16) -> 0.17
C15: R | D15: NC | E15: 0.236 | F15: 0.324 | G15: 0.332 | H15: 0.292 | I15: 0.288 | J15: 0.273 | K15: 0.286 | L15: 0.243 | M15: 0.282 | N15: 0.251 | O15: 0.264 | P15: 0.246 | Q15: 0.26 | R15: 0.309 | S15: 0.296 | T15: NC | U15: 0.271 | V15: 0.301 | W15: 0.275 | X15: 0.266 | Y15: 0.291 | Z15: 0.306 | AA15: 0.32 | AB15: 0.31 | AC15: 0.286 | AD15: 0.328 | AE15: 0.267 | AF15: 0.288 | AG15: NC | AH15: NC | AI15: 0.262 | AJ15: 0.311 | AK15: 0.329 | AL15: NC | AM15: 0.297 | AN15: 0.278 | AO15: 0.266 | AP15: 0.257 | AQ15: NC | AR15: NC | AS15: 0.3 | AT15: 0.298 | AU15: 0.247 | AV15: 0.295 | AW15: 0.293 | AX15: 0.272 | AY15: 0.275 | AZ15: 0.307 | BA15: 0.271 | BB15: 0.288 | BC15: 0.264 | BD15: 0.292 | BE15: 0.287 | BF15: 0.251 | BG15: 0.267 | BH15: 0.303 | BI15: 0.298 | BJ15: 0.24 | BK15: NC | BL15: NC | BM15: NC | BN15: =IFERROR(AVERAGE(D15:BM17),0) -> 17.260868 | BO15: =MIN(D15:BM17) -> 0.236
A16: ELEVATION | C16: LOC | D16: 1 | E16: 2 | F16: 3 | G16: 4 | H16: 5 | I16: 6 | J16: 7 | K16: 8 | L16: 9 | M16: 10 | N16: 11 | O16: 12 | P16: 13 | Q16: 14 | R16: 15 | S16: 16 | T16: 17 | U16: 18 | V16: 19 | W16: 20 | X16: 21 | Y16: 22 | Z16: 23 | AA16: 24 | AB16: 25 | AC16: 26 | AD16: 27 | AE16: 28 | AF16: 29 | AG16: 30 | AH16: 31 | AI16: 32 | AJ16: 33 | AK16: 34 | AL16: 35 | AM16: 36 | AN16: 37 | AO16: 38 | AP16: 39 | AQ16: 40 | AR16: 41 | AS16: 42 | AT16: 43 | AU16: 44 | AV16: 45 | AW16: 46 | AX16: 47 | AY16: 48 | AZ16: 49 | BA16: 50 | BB16: 51 | BC16: 52 | BD16: 53 | BE16: 54 | BF16: 55 | BG16: 56 | BH16: 57 | BI16: 58 | BJ16: 59 | BK16: 60 | BL16: 61 | BM16: 62 | BN16: AVG | BO16: MIN
A97: A | B97: 0.001-0.083 | C97: 0.204-0.233 | M97: OUTSIDE DIAMETER: | Z97: 3 | AG97: FUTURE PROJECTION | BR97: APPLIED TECHNICAL SERVICES 1049 Triad Court Marietta, Georgia 30062 Office # (770) 423-1400 Fax # (770) 514-3299 www.atslab.com | CL97: =Thickness!CL97 -> INTERNATIONAL PAPER
A98: LEGEND | B98: 0.084-0.113 | C98: 0.234-0.263 | M98: TUBE MATERIAL: | Z98: SA-210A1 | AG98: =TRUNC(MAX(D4:BM6,D7:BM9,D10:BM12,D13:BM15),3) -> 0.398 | AL98: MAX. THICKNESS | CL98: =Thickness!CL98 -> RIVERDALE MILL
B99: 0.114-0.143 | C99: 0.264-0.293 | M99: NOMINAL WALL: | Z99: 0.3 | AG99: =TRUNC(AVERAGE(D4:BM6,D7:BM9,D10:BM12,D13:BM15),3) -> 0.3 | AL99: AVG. THICKNESS | CL99: PROJECTED TUBE WALL THICKNESS - 5 YEARS
B100: 0.144-0.173 | C100: 0.294-0.323 | M100: ASME MIN: | Z100: 0.083 | AG100: =TRUNC(MIN(D4:BM6,D7:BM9,D10:BM12,D13:BM15),3) -> 0.17 | AL100: MIN. THICKNESS | CL100: =Thickness!CL100 -> NO. 1 RECOVERY BOILER
B101: 0.174-0.203 | C101: 0.324-0.999 | M101: MILL FLAG: | Z101: 0.2 | AG101: =STDEV(D4:BM6,D7:BM9,D10:BM12,D13:BM15) -> 0.030625762 | AL101: STD DEV. | AW101: =Thickness!AW101 -> Job # H449364 P.O. # 0018342455 W.O. # N/A Date: 5/05/2025 | CL101: =Thickness!CL101 -> 01 FLOOR
B102: PROJECTION
BR105: APPLIED TECHNICAL SERVICES 1049 Triad Court Marietta, Georgia 30062 Office # (770) 423-1400 Fax # (770) 514-3299 www.atslab.com
BR110: APPLIED TECHNICAL SERVICES 1325-B Cavalier Boulevard Chesapeake, Virginia 23323 (757) 558-0016 Fax (757) 558-0063 www.atslab.com
BR115: APPLIED TECHNICAL SERVICES 2312 Commerce Ctr. Dr., Suite A Rockville, Virginia 23146 (804) 550-7610 Fax (804) 550-7611 www.atslab.com

Sheet Retirement
A1: =Thickness!A1 -> 2025 | C1: =IF(ISBLANK(Thickness!C1),"",(Thickness!C1)) -> NC - NOT CLEAN; | DQ1: OBSTRUCTION
C2: TUBES NUMBERED LEFT TO RIGHT FACING WALL. | DQ2: ORIENTATION
A3: ELEVATION | C3: LOC | D3: 1 | E3: 2 | F3: 3 | G3: 4 | H3: 5 | I3: 6 | J3: 7 | K3: 8 | L3: 9 | M3: 10 | N3: 11 | O3: 12 | P3: 13 | Q3: 14 | R3: 15 | S3: 16 | T3: 17 | U3: 18 | V3: 19 | W3: 20 | X3: 21 | Y3: 22 | Z3: 23 | AA3: 24 | AB3: 25 | AC3: 26 | AD3: 27 | AE3: 28 | AF3: 29 | AG3: 30 | AH3: 31 | AI3: 32 | AJ3: 33 | AK3: 34 | AL3: 35 | AM3: 36 | AN3: 37 | AO3: 38 | AP3: 39 | AQ3: 40 | AR3: 41 | AS3: 42 | AT3: 43 | AU3: 44 | AV3: 45 | AW3: 46 | AX3: 47 | AY3: 48 | AZ3: 49 | BA3: 50 | BB3: 51 | BC3: 52 | BD3: 53 | BE3: 54 | BF3: 55 | BG3: 56 | BH3: 57 | BI3: 58 | BJ3: 59 | BK3: 60 | BL3: 61 | BM3: 62
A4: A | C4: Year | D4: May 2055 | E4: May 2055 | F4: May 2055 | G4: May 2055 | H4: May 2055 | I4: May 2055 | J4: ND | K4: May 2055 | L4: May 2055 | M4: Feb 2052 | N4: May 2055 | O4: ND | P4: May 2055 | Q4: May 2055 | R4: May 2055 | S4: May 2055 | T4: Feb 2044 | U4: May 2055 | V4: May 2055 | W4: May 2055 | X4: May 2055 | Y4: May 2055 | Z4: May 2055 | AA4: May 2055 | AB4: May 2055 | AC4: May 2055 | AD4: May 2055 | AE4: May 2055 | AF4: May 2055 | AG4: May 2055 | AH4: May 2055 | AI4: May 2055 | AJ4: May 2055 | AK4: May 2055 | AL4: May 2055 | AM4: May 2055 | AN4: May 2055 | AO4: May 2055 | AP4: Feb 2047 | AQ4: May 2055 | AR4: May 2055 | AS4: May 2055 | AT4: May 2055 | AU4: May 2055 | AV4: ND | AW4: May 2055 | AX4: May 2055 | AY4: May 2055 | AZ4: May 2055 | BA4: May 2055 | BB4: May 2055 | BC4: Apr 2053 | BD4: May 2055 | BE4: May 2055 | BF4: May 2055 | BG4: May 2055 | BH4: May 2055 | BI4: May 2055 | BJ4: May 2055 | BK4: May 2055 | BL4: May 2055 | BM4: May 2055
B5: 0 REFERENCE | D5: May 2055 | E5: May 2055 | F5: May 2055 | G5: May 2055 | H5: May 2055 | I5: May 2055 | J5: ND | K5: May 2055 | L5: May 2055 | M5: Feb 2052 | N5: May 2055 | O5: ND | P5: May 2055 | Q5: May 2055 | R5: May 2055 | S5: May 2055 | T5: Feb 2044 | U5: May 2055 | V5: May 2055 | W5: May 2055 | X5: May 2055 | Y5: May 2055 | Z5: May 2055 | AA5: May 2055 | AB5: May 2055 | AC5: May 2055 | AD5: May 2055 | AE5: May 2055 | AF5: May 2055 | AG5: May 2055 | AH5: May 2055 | AI5: May 2055 | AJ5: May 2055 | AK5: May 2055 | AL5: May 2055 | AM5: May 2055 | AN5: May 2055 | AO5: May 2055 | AP5: Feb 2047 | AQ5: May 2055 | AR5: May 2055 | AS5: May 2055 | AT5: May 2055 | AU5: May 2055 | AV5: ND | AW5: May 2055 | AX5: May 2055 | AY5: May 2055 | AZ5: May 2055 | BA5: May 2055 | BB5: May 2055 | BC5: Apr 2053 | BD5: May 2055 | BE5: May 2055 | BF5: May 2055 | BG5: May 2055 | BH5: May 2055 | BI5: May 2055 | BJ5: May 2055 | BK5: May 2055 | BL5: May 2055 | BM5: May 2055
D6: May 2055 | E6: May 2055 | F6: May 2055 | G6: May 2055 | H6: May 2055 | I6: May 2055 | J6: ND | K6: May 2055 | L6: May 2055 | M6: Feb 2052 | N6: May 2055 | O6: ND | P6: May 2055 | Q6: May 2055 | R6: May 2055 | S6: May 2055 | T6: Feb 2044 | U6: May 2055 | V6: May 2055 | W6: May 2055 | X6: May 2055 | Y6: May 2055 | Z6: May 2055 | AA6: May 2055 | AB6: May 2055 | AC6: May 2055 | AD6: May 2055 | AE6: May 2055 | AF6: May 2055 | AG6: May 2055 | AH6: May 2055 | AI6: May 2055 | AJ6: May 2055 | AK6: May 2055 | AL6: May 2055 | AM6: May 2055 | AN6: May 2055 | AO6: May 2055 | AP6: Feb 2047 | AQ6: May 2055 | AR6: May 2055 | AS6: May 2055 | AT6: May 2055 | AU6: May 2055 | AV6: ND | AW6: May 2055 | AX6: May 2055 | AY6: May 2055 | AZ6: May 2055 | BA6: May 2055 | BB6: May 2055 | BC6: Apr 2053 | BD6: May 2055 | BE6: May 2055 | BF6: May 2055 | BG6: May 2055 | BH6: May 2055 | BI6: May 2055 | BJ6: May 2055 | BK6: May 2055 | BL6: May 2055 | BM6: May 2055
A7: A | C7: Year | D7: May 2055 | E7: May 2055 | F7: May 2055 | G7: May 2055 | H7: May 2055 | I7: May 2055 | J7: May 2055 | K7: May 2055 | L7: May 2055 | M7: May 2055 | N7: May 2055 | O7: Apr 2050 | P7: May 2055 | Q7: May 2055 | R7: May 2055 | S7: May 2055 | T7: May 2055 | U7: May 2055 | V7: May 2055 | W7: May 2055 | X7: May 2055 | Y7: May 2055 | Z7: May 2055 | AA7: May 2055 | AB7: May 2055 | AC7: May 2055 | AD7: May 2055 | AE7: May 2055 | AF7: May 2055 | AG7: May 2055 | AH7: May 2055 | AI7: May 2055 | AJ7: May 2055 | AK7: May 2055 | AL7: May 2055 | AM7: May 2055 | AN7: May 2055 | AO7: May 2055 | AP7: May 2055 | AQ7: May 2055 | AR7: May 2055 | AS7: May 2055 | AT7: May 2055 | AU7: May 2055 | AV7: May 2055 | AW7: May 2055 | AX7: May 2051 | AY7: May 2055 | AZ7: May 2055 | BA7: May 2055 | BB7: Feb 2052 | BC7: May 2055 | BD7: May 2055 | BE7: Feb 2055 | BF7: May 2055 | BG7: May 2055 | BH7: Mar 2052 | BI7: Feb 2055 | BJ7: May 2055 | BK7: Jul 2053 | BL7: Mar 2043 | BM7: Oct 2051
B8: -6 FEET | D8: May 2055 | E8: May 2055 | F8: May 2055 | G8: May 2055 | H8: May 2055 | I8: May 2055 | J8: May 2055 | K8: May 2055 | L8: May 2055 | M8: May 2055 | N8: May 2055 | O8: Apr 2050 | P8: May 2055 | Q8: May 2055 | R8: May 2055 | S8: May 2055 | T8: May 2055 | U8: May 2055 | V8: May 2055 | W8: May 2055 | X8: May 2055 | Y8: May 2055 | Z8: May 2055 | AA8: May 2055 | AB8: May 2055 | AC8: May 2055 | AD8: May 2055 | AE8: May 2055 | AF8: May 2055 | AG8: May 2055 | AH8: May 2055 | AI8: May 2055 | AJ8: May 2055 | AK8: May 2055 | AL8: May 2055 | AM8: May 2055 | AN8: May 2055 | AO8: May 2055 | AP8: May 2055 | AQ8: May 2055 | AR8: May 2055 | AS8: May 2055 | AT8: May 2055 | AU8: May 2055 | AV8: May 2055 | AW8: May 2055 | AX8: May 2051 | AY8: May 2055 | AZ8: May 2055 | BA8: May 2055 | BB8: Feb 2052 | BC8: May 2055 | BD8: May 2055 | BE8: Feb 2055 | BF8: May 2055 | BG8: May 2055 | BH8: Mar 2052 | BI8: Feb 2055 | BJ8: May 2055 | BK8: Jul 2053 | BL8: Mar 2043 | BM8: Oct 2051
D9: May 2055 | E9: May 2055 | F9: May 2055 | G9: May 2055 | H9: May 2055 | I9: May 2055 | J9: May 2055 | K9: May 2055 | L9: May 2055 | M9: May 2055 | N9: May 2055 | O9: Apr 2050 | P9: May 2055 | Q9: May 2055 | R9: May 2055 | S9: May 2055 | T9: May 2055 | U9: May 2055 | V9: May 2055 | W9: May 2055 | X9: May 2055 | Y9: May 2055 | Z9: May 2055 | AA9: May 2055 | AB9: May 2055 | AC9: May 2055 | AD9: May 2055 | AE9: May 2055 | AF9: May 2055 | AG9: May 2055 | AH9: May 2055 | AI9: May 2055 | AJ9: May 2055 | AK9: May 2055 | AL9: May 2055 | AM9: May 2055 | AN9: May 2055 | AO9: May 2055 | AP9: May 2055 | AQ9: May 2055 | AR9: May 2055 | AS9: May 2055 | AT9: May 2055 | AU9: May 2055 | AV9: May 2055 | AW9: May 2055 | AX9: May 2051 | AY9: May 2055 | AZ9: May 2055 | BA9: May 2055 | BB9: Feb 2052 | BC9: May 2055 | BD9: May 2055 | BE9: Feb 2055 | BF9: May 2055 | BG9: May 2055 | BH9: Mar 2052 | BI9: Feb 2055 | BJ9: May 2055 | BK9: Jul 2053 | BL9: Mar 2043 | BM9: Oct 2051
A10: A | C10: Year | D10: May 2055 | E10: May 2055 | F10: May 2055 | G10: May 2055 | H10: May 2055 | I10: May 2055 | J10: ND | K10: Aug 2041 | L10: Sep 2054 | M10: May 2055 | N10: May 2055 | O10: May 2055 | P10: May 2055 | Q10: May 2055 | R10: May 2055 | S10: May 2055 | T10: May 2055 | U10: Apr 2054 | V10: May 2055 | W10: May 2055 | X10: May 2055 | Y10: May 2055 | Z10: May 2055 | AA10: May 2055 | AB10: May 2055 | AC10: Aug 2043 | AD10: Dec 2048 | AE10: May 2055 | AF10: May 2055 | AG10: May 2055 | AH10: May 2055 | AI10: May 2055 | AJ10: May 2055 | AK10: Jul 2054 | AL10: Mar 2054 | AM10: May 2055 | AN10: May 2055 | AO10: May 2055 | AP10: May 2055 | AQ10: May 2055 | AR10: May 2055 | AS10: May 2055 | AT10: May 2055 | AU10: May 2055 | AV10: May 2055 | AW10: Dec 2050 | AX10: May 2055 | AY10: May 2055 | AZ10: May 2055 | BA10: May 2055 | BB10: May 2055 | BC10: May 2055 | BD10: May 2055 | BE10: May 2055 | BF10: Apr 2046 | BG10: Jan 2053 | BH10: Nov 2054 | BI10: May 2055 | BJ10: May 2055 | BK10: May 2055 | BL10: Feb 2046 | BM10: Mar 2039
B11: -12 FEET | D11: May 2055 | E11: May 2055 | F11: May 2055 | G11: May 2055 | H11: May 2055 | I11: May 2055 | J11: ND | K11: Aug 2041 | L11: Sep 2054 | M11: May 2055 | N11: May 2055 | O11: May 2055 | P11: May 2055 | Q11: May 2055 | R11: May 2055 | S11: May 2055 | T11: May 2055 | U11: Apr 2054 | V11: May 2055 | W11: May 2055 | X11: May 2055 | Y11: May 2055 | Z11: May 2055 | AA11: May 2055 | AB11: May 2055 | AC11: Aug 2043 | AD11: Dec 2048 | AE11: May 2055 | AF11: May 2055 | AG11: May 2055 | AH11: May 2055 | AI11: May 2055 | AJ11: May 2055 | AK11: Jul 2054 | AL11: Mar 2054 | AM11: May 2055 | AN11: May 2055 | AO11: May 2055 | AP11: May 2055 | AQ11: May 2055 | AR11: May 2055 | AS11: May 2055 | AT11: May 2055 | AU11: May 2055 | AV11: May 2055 | AW11: Dec 2050 | AX11: May 2055 | AY11: May 2055 | AZ11: May 2055 | BA11: May 2055 | BB11: May 2055 | BC11: May 2055 | BD11: May 2055 | BE11: May 2055 | BF11: Apr 2046 | BG11: Jan 2053 | BH11: Nov 2054 | BI11: May 2055 | BJ11: May 2055 | BK11: May 2055 | BL11: Feb 2046 | BM11: Mar 2039
D12: May 2055 | E12: May 2055 | F12: May 2055 | G12: May 2055 | H12: May 2055 | I12: May 2055 | J12: ND | K12: Aug 2041 | L12: Sep 2054 | M12: May 2055 | N12: May 2055 | O12: May 2055 | P12: May 2055 | Q12: May 2055 | R12: May 2055 | S12: May 2055 | T12: May 2055 | U12: Apr 2054 | V12: May 2055 | W12: May 2055 | X12: May 2055 | Y12: May 2055 | Z12: May 2055 | AA12: May 2055 | AB12: May 2055 | AC12: Aug 2043 | AD12: Dec 2048 | AE12: May 2055 | AF12: May 2055 | AG12: May 2055 | AH12: May 2055 | AI12: May 2055 | AJ12: May 2055 | AK12: Jul 2054 | AL12: Mar 2054 | AM12: May 2055 | AN12: May 2055 | AO12: May 2055 | AP12: May 2055 | AQ12: May 2055 | AR12: May 2055 | AS12: May 2055 | AT12: May 2055 | AU12: May 2055 | AV12: May 2055 | AW12: Dec 2050 | AX12: May 2055 | AY12: May 2055 | AZ12: May 2055 | BA12: May 2055 | BB12: May 2055 | BC12: May 2055 | BD12: May 2055 | BE12: May 2055 | BF12: Apr 2046 | BG12: Jan 2053 | BH12: Nov 2054 | BI12: May 2055 | BJ12: May 2055 | BK12: May 2055 | BL12: Feb 2046 | BM12: Mar 2039
A13: A | C13: Year | D13: Jul 2045 | E13: Jul 2040 | F13: May 2055 | G13: May 2055 | H13: May 2055 | I13: Jan 2048 | J13: May 2055 | K13: May 2055 | L13: Dec 2047 | M13: Feb 2052 | N13: Nov 2050 | O13: Feb 2039 | P13: Apr 2047 | Q13: Sep 2041 | R13: May 2055 | S13: Dec 2050 | T13: ND | U13: Oct 2054 | V13: May 2055 | W13: May 2055 | X13: Jul 2053 | Y13: May 2055 | Z13: May 2055 | AA13: May 2055 | AB13: May 2055 | AC13: May 2055 | AD13: May 2055 | AE13: Mar 2055 | AF13: May 2055 | AG13: May 2055 | AH13: ND | AI13: Nov 2051 | AJ13: May 2055 | AK13: May 2055 | AL13: May 2055 | AM13: May 2055 | AN13: May 2055 | AO13: May 2055 | AP13: Jan 2052 | AQ13: May 2055 | AR13: May 2055 | AS13: May 2055 | AT13: May 2055 | AU13: Apr 2048 | AV13: Jan 2053 | AW13: May 2055 | AX13: Apr 2047 | AY13: May 2045 | AZ13: May 2055 | BA13: Dec 2049 | BB13: May 2055 | BC13: Aug 2035 | BD13: May 2055 | BE13: Oct 2044 | BF13: Jan 2041 | BG13: Sep 2044 | BH13: Jan 2050 | BI13: May 2055 | BJ13: Jul 2040 | BK13: May 2055 | BL13: ND | BM13: ND
B14: -18 FEET | D14: Jul 2045 | E14: Jul 2040 | F14: May 2055 | G14: May 2055 | H14: May 2055 | I14: Jan 2048 | J14: May 2055 | K14: May 2055 | L14: Dec 2047 | M14: Feb 2052 | N14: Nov 2050 | O14: Feb 2039 | P14: Apr 2047 | Q14: Sep 2041 | R14: May 2055 | S14: Dec 2050 | T14: ND | U14: Oct 2054 | V14: May 2055 | W14: May 2055 | X14: Jul 2053 | Y14: May 2055 | Z14: May 2055 | AA14: May 2055 | AB14: May 2055 | AC14: May 2055 | AD14: May 2055 | AE14: Mar 2055 | AF14: May 2055 | AG14: May 2055 | AH14: ND | AI14: Nov 2051 | AJ14: May 2055 | AK14: May 2055 | AL14: May 2055 | AM14: May 2055 | AN14: May 2055 | AO14: May 2055 | AP14: Jan 2052 | AQ14: May 2055 | AR14: May 2055 | AS14: May 2055 | AT14: May 2055 | AU14: Apr 2048 | AV14: Jan 2053 | AW14: May 2055 | AX14: Apr 2047 | AY14: May 2045 | AZ14: May 2055 | BA14: Dec 2049 | BB14: May 2055 | BC14: Aug 2035 | BD14: May 2055 | BE14: Oct 2044 | BF14: Jan 2041 | BG14: Sep 2044 | BH14: Jan 2050 | BI14: May 2055 | BJ14: Jul 2040 | BK14: May 2055 | BL14: ND | BM14: ND
D15: Jul 2045 | E15: Jul 2040 | F15: May 2055 | G15: May 2055 | H15: May 2055 | I15: Jan 2048 | J15: May 2055 | K15: May 2055 | L15: Dec 2047 | M15: Feb 2052 | N15: Nov 2050 | O15: Feb 2039 | P15: Apr 2047 | Q15: Sep 2041 | R15: May 2055 | S15: Dec 2050 | T15: ND | U15: Oct 2054 | V15: May 2055 | W15: May 2055 | X15: Jul 2053 | Y15: May 2055 | Z15: May 2055 | AA15: May 2055 | AB15: May 2055 | AC15: May 2055 | AD15: May 2055 | AE15: Mar 2055 | AF15: May 2055 | AG15: May 2055 | AH15: ND | AI15: Nov 2051 | AJ15: May 2055 | AK15: May 2055 | AL15: May 2055 | AM15: May 2055 | AN15: May 2055 | AO15: May 2055 | AP15: Jan 2052 | AQ15: May 2055 | AR15: May 2055 | AS15: May 2055 | AT15: May 2055 | AU15: Apr 2048 | AV15: Jan 2053 | AW15: May 2055 | AX15: Apr 2047 | AY15: May 2045 | AZ15: May 2055 | BA15: Dec 2049 | BB15: May 2055 | BC15: Aug 2035 | BD15: May 2055 | BE15: Oct 2044 | BF15: Jan 2041 | BG15: Sep 2044 | BH15: Jan 2050 | BI15: May 2055 | BJ15: Jul 2040 | BK15: May 2055 | BL15: ND | BM15: ND
A16: ELEVATION | C16: LOC | D16: 1 | E16: 2 | F16: 3 | G16: 4 | H16: 5 | I16: 6 | J16: 7 | K16: 8 | L16: 9 | M16: 10 | N16: 11 | O16: 12 | P16: 13 | Q16: 14 | R16: 15 | S16: 16 | T16: 17 | U16: 18 | V16: 19 | W16: 20 | X16: 21 | Y16: 22 | Z16: 23 | AA16: 24 | AB16: 25 | AC16: 26 | AD16: 27 | AE16: 28 | AF16: 29 | AG16: 30 | AH16: 31 | AI16: 32 | AJ16: 33 | AK16: 34 | AL16: 35 | AM16: 36 | AN16: 37 | AO16: 38 | AP16: 39 | AQ16: 40 | AR16: 41 | AS16: 42 | AT16: 43 | AU16: 44 | AV16: 45 | AW16: 46 | AX16: 47 | AY16: 48 | AZ16: 49 | BA16: 50 | BB16: 51 | BC16: 52 | BD16: 53 | BE16: 54 | BF16: 55 | BG16: 56 | BH16: 57 | BI16: 58 | BJ16: 59 | BK16: 60 | BL16: 61 | BM16: 62
B97: PROJECTED TO REACH TMIN: | M97: NOTE: CORROSION RATE IS BASED ON COMPARISON OF | AG97: EARLIEST DATE OF PROJECTED RETIREMENT: | BR97: APPLIED TECHNICAL SERVICES 1049 Triad Court Marietta, Georgia 30062 Office # (770) 423-1400 Fax # (770) 514-3299 www.atslab.com | CL97: =Thickness!CL97 -> INTERNATIONAL PAPER
A98: LEGEND | B98: + 5 YEARS (or no data) | CL98: =Thickness!CL98 -> RIVERDALE MILL
B99: WITHIN 5 YEARS | M99: 2020, 2022, 2023, 2024, 2025 | CL99: PROJECTED TUBE RETIREMENT DATE
B100: WITHIN 3 YEARS | M100: INSPECTION DATA | AG100: August 2035 | CL100: =Thickness!CL100 -> NO. 1 RECOVERY BOILER
B101: WITHIN 1 YEAR | M101: ND | R101: NO COMPARISON DATA | AW101: =Thickness!AW101 -> Job # H449364 P.O. # 0018342455 W.O. # N/A Date: 5/05/2025 | CL101: =Thickness!CL101 -> 01 FLOOR
B102: RETIREMENT
BR105: APPLIED TECHNICAL SERVICES 1049 Triad Court Marietta, Georgia 30062 Office # (770) 423-1400 Fax # (770) 514-3299 www.atslab.com
BR110: APPLIED TECHNICAL SERVICES 1325-B Cavalier Boulevard Chesapeake, Virginia 23323 (757) 558-0016 Fax (757) 558-0063 www.atslab.com
BR115: APPLIED TECHNICAL SERVICES 2312 Commerce Ctr. Dr., Suite A Rockville, Virginia 23146 (804) 550-7610 Fax (804) 550-7611 www.atslab.com

Sheet Low
A1: =Thickness!A1 -> 2025 | C1: =IF(ISBLANK(Thickness!C1),"",(Thickness!C1)) -> NC - NOT CLEAN; | DQ1: OBSTRUCTION
C2: TUBES NUMBERED LEFT TO RIGHT FACING WALL. LOW THICKNESS MEASUREMENTS ARE IN INCHES. | DQ2: ORIENTATION
A3: ELEVATION | C3: LOC | D3: 1 | E3: 2 | F3: 3 | G3: 4 | H3: 5 | I3: 6 | J3: 7 | K3: 8 | L3: 9 | M3: 10 | N3: 11 | O3: 12 | P3: 13 | Q3: 14 | R3: 15 | S3: 16 | T3: 17 | U3: 18 | V3: 19 | W3: 20 | X3: 21 | Y3: 22 | Z3: 23 | AA3: 24 | AB3: 25 | AC3: 26 | AD3: 27 | AE3: 28 | AF3: 29 | AG3: 30 | AH3: 31 | AI3: 32 | AJ3: 33 | AK3: 34 | AL3: 35 | AM3: 36 | AN3: 37 | AO3: 38 | AP3: 39 | AQ3: 40 | AR3: 41 | AS3: 42 | AT3: 43 | AU3: 44 | AV3: 45 | AW3: 46 | AX3: 47 | AY3: 48 | AZ3: 49 | BA3: 50 | BB3: 51 | BC3: 52 | BD3: 53 | BE3: 54 | BF3: 55 | BG3: 56 | BH3: 57 | BI3: 58 | BJ3: 59 | BK3: 60 | BL3: 61 | BM3: 62 | BN3: AVG | BO3: MIN
A4: A | C4: LOWEST | D4: =MIN(Thickness!D4:D6) -> 0.349 | E4: =MIN(Thickness!E4:E6) -> 0.344 | F4: =MIN(Thickness!F4:F6) -> 0.343 | G4: =MIN(Thickness!G4:G6) -> 0.333 | H4: =MIN(Thickness!H4:H6) -> 0.352 | I4: =MIN(Thickness!I4:I6) -> 0.351 | J4: =MIN(Thickness!J4:J6) -> 0.344 | K4: =MIN(Thickness!K4:K6) -> 0.331 | ... BM4: =MIN(Thickness!BM4:BM6) -> 0.344 | BN4: =IFERROR(AVERAGE(D4:BM6),0) -> 0.32730645 | BO4: =MIN(D4:BM6) -> 0.297
A5: 0.083 | B5: 0 REFERENCE | BN5: =IFERROR(AVERAGE(D5:BM7),0) -> 0.30520968 | BO5: =MIN(D5:BM7) -> 0.284
BN6: =IFERROR(AVERAGE(D6:BM8),0) -> 0.30520968 | BO6: =MIN(D6:BM8) -> 0.284
A7: A | C7: LOWEST | D7: =MIN(Thickness!D7:D9) -> 0.332 | E7: =MIN(Thickness!E7:E9) -> 0.325 | F7: =MIN(Thickness!F7:F9) -> 0.323 | G7: =MIN(Thickness!G7:G9) -> 0.308 | H7: =MIN(Thickness!H7:H9) -> 0.311 | I7: =MIN(Thickness!I7:I9) -> 0.315 | J7: =MIN(Thickness!J7:J9) -> 0.319 | K7: =MIN(Thickness!K7:K9) -> 0.313 | ... BM7: =MIN(Thickness!BM7:BM9) -> 0.299 | BN7: =IFERROR(AVERAGE(D7:BM9),0) -> 0.30520968 | BO7: =MIN(D7:BM9) -> 0.284
A8: 0.083 | B8: -6 FEET | BN8: =IFERROR(AVERAGE(D8:BM10),0) -> 0.31276471 | BO8: =MIN(D8:BM10) -> 0.277
BN9: =IFERROR(AVERAGE(D9:BM11),0) -> 0.31276471 | BO9: =MIN(D9:BM11) -> 0.277
A10: A | C10: LOWEST | D10: NC | E10: NC | F10: NC | G10: NC | H10: =MIN(Thickness!H10:H12) -> 0.323 | I10: =MIN(Thickness!I10:I12) -> 0.323 | J10: =MIN(Thickness!J10:J12) -> 0.381 | K10: =MIN(Thickness!K10:K12) -> 0.277 | L10: =MIN(Thickness!L10:L12) -> 0.307 | M10: =MIN(Thickness!M10:M12) -> 0.311 | N10: =MIN(Thickness!N10:N12) -> 0.308 | O10: =MIN(Thickness!O10:O12) -> 0.315 | ... AA10: =MIN(Thickness!AA10:AA12) -> 0.306 | AB10: NC | AC10: =MIN(Thickness!AC10:AC12) -> 0.312 | AD10: NC | AE10: =MIN(Thickness!AE10:AE12) -> 0.321 | AF10: =MIN(Thickness!AF10:AF12) -> 0.33 | AG10: =MIN(Thickness!AG10:AG12) -> 0.315 | AH10: =MIN(Thickness!AH10:AH12) -> 0.315 | AI10: =MIN(Thickness!AI10:AI12) -> 0.33 | AJ10: NC | AK10: =MIN(Thickness!AK10:AK12) -> 0.304 | AL10: =MIN(Thickness!AL10:AL12) -> 0.354 | AM10: =MIN(Thickness!AM10:AM12) -> 0.309 | AN10: =MIN(Thickness!AN10:AN12) -> 0.314 | AO10: =MIN(Thickness!AO10:AO12) -> 0.299 | AP10: =MIN(Thickness!AP10:AP12) -> 0.31 | AQ10: =MIN(Thickness!AQ10:AQ12) -> 0.332 | AR10: =MIN(Thickness!AR10:AR12) -> 0.321 | ... BH10: =MIN(Thickness!BH10:BH12) -> 0.301 | BI10: NC | BJ10: =MIN(Thickness!BJ10:BJ12) -> 0.312 | BK10: NC | BL10: NC | BM10: NC | BN10: =IFERROR(AVERAGE(D10:BM12),0) -> 0.31276471 | BO10: =MIN(D10:BM12) -> 0.277
A11: 0.083 | B11: -12 FEET | D11: NC | E11: NC | F11: NC | G11: NC | AB11: NC | AD11: NC | AJ11: NC | BI11: NC | BK11: NC | BL11: NC | BM11: NC | BN11: =IFERROR(AVERAGE(D11:BM13),0) -> 0 | BO11: =MIN(D11:BM13) -> 0
D12: NC | E12: NC | F12: NC | G12: NC | AB12: NC | AD12: NC | AJ12: NC | BI12: NC | BK12: NC | BL12: NC | BM12: NC | BN12: =IFERROR(AVERAGE(D12:BM14),0) -> 0 | BO12: =MIN(D12:BM14) -> 0
A13: A | C13: LOWEST | D13: NC | E13: NC | F13: NC | G13: NC | H13: NC | I13: NC | J13: NC | K13: NC | L13: NC | M13: NC | N13: NC | O13: NC | P13: NC | Q13: NC | R13: NC | S13: NC | T13: NC | U13: NC | V13: NC | W13: NC | X13: NC | Y13: NC | Z13: NC | AA13: NC | AB13: NC | AC13: NC | AD13: NC | AE13: NC | AF13: NC | AG13: NC | AH13: NC | AI13: NC | AJ13: NC | AK13: NC | AL13: NC | AM13: NC | AN13: NC | AO13: NC | AP13: NC | AQ13: NC | AR13: NC | AS13: NC | AT13: NC | AU13: NC | AV13: NC | AW13: NC | AX13: NC | AY13: NC | AZ13: NC | BA13: NC | BB13: NC | BC13: NC | BD13: NC | BE13: NC | BF13: NC | BG13: NC | BH13: NC | BI13: NC | BJ13: NC | BK13: NC | BL13: NC | BM13: NC | BN13: =IFERROR(AVERAGE(D13:BM15),0) -> 0 | BO13: =MIN(D13:BM15) -> 0
A14: 0.083 | B14: -18 FEET | D14: NC | E14: NC | F14: NC | G14: NC | H14: NC | I14: NC | J14: NC | K14: NC | L14: NC | M14: NC | N14: NC | O14: NC | P14: NC | Q14: NC | R14: NC | S14: NC | T14: NC | U14: NC | V14: NC | W14: NC | X14: NC | Y14: NC | Z14: NC | AA14: NC | AB14: NC | AC14: NC | AD14: NC | AE14: NC | AF14: NC | AG14: NC | AH14: NC | AI14: NC | AJ14: NC | AK14: NC | AL14: NC | AM14: NC | AN14: NC | AO14: NC | AP14: NC | AQ14: NC | AR14: NC | AS14: NC | AT14: NC | AU14: NC | AV14: NC | AW14: NC | AX14: NC | AY14: NC | AZ14: NC | BA14: NC | BB14: NC | BC14: NC | BD14: NC | BE14: NC | BF14: NC | BG14: NC | BH14: NC | BI14: NC | BJ14: NC | BK14: NC | BL14: NC | BM14: NC | BN14: =IFERROR(AVERAGE(D14:BM16),0) -> 31.5 | BO14: =MIN(D14:BM16) -> 1
